Workbook
Name offshore_region: Storage_projects!$D$9:$D$100
Name onshore_nuts1: Storage_projects!$E$9:$E$100
Name onshore_or_offshore: Storage_projects!$I$9:$I$100
Name operational_category_high: Storage_projects!$C$9:$C$100
Name operational_category_low: Storage_projects!$A$9:$A$100
Name operational_category_medium: Storage_projects!$B$9:$B$100
Name storage_capacity_2030: Storage_projects!$Q$9:$Q$100
Name storage_capacity_2040: Storage_projects!$W$9:$W$100
Name storage_capacity_2050: Storage_projects!$X$9:$X$100

Sheet Info
A1: Date | B1: 46272.416
A2: Project | B2: Mopo
A3: Name | B3: Marit van Hout
A4: Organisation | B4: PBL
A5: Content | B5: This document contains storage projects in Europe mentioned by JRC (2024) and CATF (2023) (capacity + expected year of operation), where JRC 2024 provides more conservative figures. These datasets are complemented by expert judgment on when these storage facilities are available assuming a low, medium and high storage scenario. For 2030, the EU has set a legal target - see Net-zero Industry Act (NZIA) - to permanently store CO2 (50 Mtpa). This however excludes storage sites in Norway and UK. It is assumed that in none of the scenarios this target is met. According to EC (2026), the maximum permanent storage of CO2 on EU territory is expected to be 29 Mtpa, of which 10 Mtpa in the Netherlands. This mainly involves the Aramis project that will likely not be operational in 2030 yet. For 2050, the EC states that to achieve climate neutrality in 2050, a capacity to permanently store CO2 of 250 Mtpa is required (this can involve storages outside EU) (i.e. aim not a target). The low scenario represents a conservative capacity scenario, assuming that the uptake is relatively slow due to implementation hurdles. This especially holds for onshore storage due to more legal, social, economical and technical challenges resulting in zero onshore storage capacity in 2050. The medium scenario assumes that sufficient storage wil be in place in 2050 to meet EU's aim (250 Mtpa + roughly 25 Mtpa 'reserved' for UK/NO). In the high scenario, the uptake is progressing quickly assuming that all listed projects in the JRC (2024) and CATF (2023) study are operational by 2050. In addition to the listed projects, it is assumed that Germany invests significantly in its own offshore storage potential, assuming a capacity of 60 Mtpa operational in 2050 in the high scenario (based on GEOSTOR, 2025). This is especially of interest to the NL/BE Industrial Case study assessment (Mopo WP5.3).
A24: Scope | B24: EU storage projects in Megaton of CO2 per annum (Mtpa) for 2030, 2040 and 2050. The onshore storage capacity is defined on NUTS1 level, and offshore storage capacity is defined on OFF3 level.
A27: Data sources | B27: JRC, 2024: | C27: https://publications.jrc.ec.europa.eu/repository/bitstream/JRC136709/JRC136709_01.pdf
B28: CATF, 2023 | C28: https://www.catf.us/ccsmapeurope/
B29: GEOSTOR, 2025 | C29: https://cdrmare.de/wp-content/uploads/2025/04/geostor_ergebnisse_phase1.pdf
B30: EC, 2026 | C30: REPORT FROM THE COMMISSION TO THE EUROPEAN PARLIAMENT AND THE COUNCIL on the progress towards reaching the Union-wide target for CO2 injection capacity. COM/2026/252 final

Sheet Onshore_storage_potentials
A1: country | B1: year | C1: low | D1: medium | E1: high | F1: unit
A2: DK | B2: 2030 | C2: =SUMIFS(storage_capacity_2030,onshore_or_offshore,"Onshore storage",operational_category_low,1,onshore_nuts1,A2)+IF(B2=2040,SUMIFS(storage_capacity_2040,onshore_or_offshore,"Onshore storage",operational_category_low,2,onshore_nuts1,A2))+IF(B2=2050,SUMIFS(storage_capacity_2040,onshore_or_offshore,"Onshore storage",operational_category_low,2,onshore_nuts1,A2))+IF(B2=2050,SUMIFS(storage_capacity_2050,onshore_or_offshore,"Onshore storage",operational_category_low,3,onshore_nuts1,A2)) -> 0 | D2: =SUMIFS(storage_capacity_2030,onshore_or_offshore,"Onshore storage",operational_category_medium,1,onshore_nuts1,A2)+IF(B2=2040,SUMIFS(storage_capacity_2040,onshore_or_offshore,"Onshore storage",operational_category_medium,2,onshore_nuts1,A2))+IF(B2=2050,SUMIFS(storage_capacity_2040,onshore_or_offshore,"Onshore storage",operational_category_medium,2,onshore_nuts1,A2))+IF(B2=2050,SUMIFS(storage_capacity_2050,onshore_or_offshore,"Onshore storage",operational_category_medium,3,onshore_nuts1,A2)) -> 0 | E2: =SUMIFS(storage_capacity_2030,onshore_or_offshore,"Onshore storage",operational_category_high,1,onshore_nuts1,A2)+IF(B2=2040,SUMIFS(storage_capacity_2040,onshore_or_offshore,"Onshore storage",operational_category_high,2,onshore_nuts1,A2))+IF(B2=2050,SUMIFS(storage_capacity_2040,onshore_or_offshore,"Onshore storage",operational_category_high,2,onshore_nuts1,A2))+IF(B2=2050,SUMIFS(storage_capacity_2050,onshore_or_offshore,"Onshore storage",operational_category_high,3,onshore_nuts1,A2)) -> 0 | F2: Mtpa
A3: FR | B3: 2030 | C3: =SUMIFS(storage_capacity_2030,onshore_or_offshore,"Onshore storage",operational_category_low,1,onshore_nuts1,A3)+IF(B3=2040,SUMIFS(storage_capacity_2040,onshore_or_offshore,"Onshore storage",operational_category_low,2,onshore_nuts1,A3))+IF(B3=2050,SUMIFS(storage_capacity_2040,onshore_or_offshore,"Onshore storage",operational_category_low,2,onshore_nuts1,A3))+IF(B3=2050,SUMIFS(storage_capacity_2050,onshore_or_offshore,"Onshore storage",operational_category_low,3,onshore_nuts1,A3)) -> 0 | D3: =SUMIFS(storage_capacity_2030,onshore_or_offshore,"Onshore storage",operational_category_medium,1,onshore_nuts1,A3)+IF(B3=2040,SUMIFS(storage_capacity_2040,onshore_or_offshore,"Onshore storage",operational_category_medium,2,onshore_nuts1,A3))+IF(B3=2050,SUMIFS(storage_capacity_2040,onshore_or_offshore,"Onshore storage",operational_category_medium,2,onshore_nuts1,A3))+IF(B3=2050,SUMIFS(storage_capacity_2050,onshore_or_offshore,"Onshore storage",operational_category_medium,3,onshore_nuts1,A3)) -> 0 | E3: =SUMIFS(storage_capacity_2030,onshore_or_offshore,"Onshore storage",operational_category_high,1,onshore_nuts1,A3)+IF(B3=2040,SUMIFS(storage_capacity_2040,onshore_or_offshore,"Onshore storage",operational_category_high,2,onshore_nuts1,A3))+IF(B3=2050,SUMIFS(storage_capacity_2040,onshore_or_offshore,"Onshore storage",operational_category_high,2,onshore_nuts1,A3))+IF(B3=2050,SUMIFS(storage_capacity_2050,onshore_or_offshore,"Onshore storage",operational_category_high,3,onshore_nuts1,A3)) -> 0 | F3: Mtpa
A4: RO | B4: 2030 | C4: =SUMIFS(storage_capacity_2030,onshore_or_offshore,"Onshore storage",operational_category_low,1,onshore_nuts1,A4)+IF(B4=2040,SUMIFS(storage_capacity_2040,onshore_or_offshore,"Onshore storage",operational_category_low,2,onshore_nuts1,A4))+IF(B4=2050,SUMIFS(storage_capacity_2040,onshore_or_offshore,"Onshore storage",operational_category_low,2,onshore_nuts1,A4))+IF(B4=2050,SUMIFS(storage_capacity_2050,onshore_or_offshore,"Onshore storage",operational_category_low,3,onshore_nuts1,A4)) -> 0 | D4: =SUMIFS(storage_capacity_2030,onshore_or_offshore,"Onshore storage",operational_category_medium,1,onshore_nuts1,A4)+IF(B4=2040,SUMIFS(storage_capacity_2040,onshore_or_offshore,"Onshore storage",operational_category_medium,2,onshore_nuts1,A4))+IF(B4=2050,SUMIFS(storage_capacity_2040,onshore_or_offshore,"Onshore storage",operational_category_medium,2,onshore_nuts1,A4))+IF(B4=2050,SUMIFS(storage_capacity_2050,onshore_or_offshore,"Onshore storage",operational_category_medium,3,onshore_nuts1,A4)) -> 0 | E4: =SUMIFS(storage_capacity_2030,onshore_or_offshore,"Onshore storage",operational_category_high,1,onshore_nuts1,A4)+IF(B4=2040,SUMIFS(storage_capacity_2040,onshore_or_offshore,"Onshore storage",operational_category_high,2,onshore_nuts1,A4))+IF(B4=2050,SUMIFS(storage_capacity_2040,onshore_or_offshore,"Onshore storage",operational_category_high,2,onshore_nuts1,A4))+IF(B4=2050,SUMIFS(storage_capacity_2050,onshore_or_offshore,"Onshore storage",operational_category_high,3,onshore_nuts1,A4)) -> 0 | F4: Mtpa
A5: HR | B5: 2030 | C5: =SUMIFS(storage_capacity_2030,onshore_or_offshore,"Onshore storage",operational_category_low,1,onshore_nuts1,A5)+IF(B5=2040,SUMIFS(storage_capacity_2040,onshore_or_offshore,"Onshore storage",operational_category_low,2,onshore_nuts1,A5))+IF(B5=2050,SUMIFS(storage_capacity_2040,onshore_or_offshore,"Onshore storage",operational_category_low,2,onshore_nuts1,A5))+IF(B5=2050,SUMIFS(storage_capacity_2050,onshore_or_offshore,"Onshore storage",operational_category_low,3,onshore_nuts1,A5)) -> 0 | D5: =SUMIFS(storage_capacity_2030,onshore_or_offshore,"Onshore storage",operational_category_medium,1,onshore_nuts1,A5)+IF(B5=2040,SUMIFS(storage_capacity_2040,onshore_or_offshore,"Onshore storage",operational_category_medium,2,onshore_nuts1,A5))+IF(B5=2050,SUMIFS(storage_capacity_2040,onshore_or_offshore,"Onshore storage",operational_category_medium,2,onshore_nuts1,A5))+IF(B5=2050,SUMIFS(storage_capacity_2050,onshore_or_offshore,"Onshore storage",operational_category_medium,3,onshore_nuts1,A5)) -> 0 | E5: =SUMIFS(storage_capacity_2030,onshore_or_offshore,"Onshore storage",operational_category_high,1,onshore_nuts1,A5)+IF(B5=2040,SUMIFS(storage_capacity_2040,onshore_or_offshore,"Onshore storage",operational_category_high,2,onshore_nuts1,A5))+IF(B5=2050,SUMIFS(storage_capacity_2040,onshore_or_offshore,"Onshore storage",operational_category_high,2,onshore_nuts1,A5))+IF(B5=2050,SUMIFS(storage_capacity_2050,onshore_or_offshore,"Onshore storage",operational_category_high,3,onshore_nuts1,A5)) -> 0 | F5: Mtpa
A6: BG | B6: 2030 | C6: =SUMIFS(storage_capacity_2030,onshore_or_offshore,"Onshore storage",operational_category_low,1,onshore_nuts1,A6)+IF(B6=2040,SUMIFS(storage_capacity_2040,onshore_or_offshore,"Onshore storage",operational_category_low,2,onshore_nuts1,A6))+IF(B6=2050,SUMIFS(storage_capacity_2040,onshore_or_offshore,"Onshore storage",operational_category_low,2,onshore_nuts1,A6))+IF(B6=2050,SUMIFS(storage_capacity_2050,onshore_or_offshore,"Onshore storage",operational_category_low,3,onshore_nuts1,A6)) -> 0 | D6: =SUMIFS(storage_capacity_2030,onshore_or_offshore,"Onshore storage",operational_category_medium,1,onshore_nuts1,A6)+IF(B6=2040,SUMIFS(storage_capacity_2040,onshore_or_offshore,"Onshore storage",operational_category_medium,2,onshore_nuts1,A6))+IF(B6=2050,SUMIFS(storage_capacity_2040,onshore_or_offshore,"Onshore storage",operational_category_medium,2,onshore_nuts1,A6))+IF(B6=2050,SUMIFS(storage_capacity_2050,onshore_or_offshore,"Onshore storage",operational_category_medium,3,onshore_nuts1,A6)) -> 0 | E6: =SUMIFS(storage_capacity_2030,onshore_or_offshore,"Onshore storage",operational_category_high,1,onshore_nuts1,A6)+IF(B6=2040,SUMIFS(storage_capacity_2040,onshore_or_offshore,"Onshore storage",operational_category_high,2,onshore_nuts1,A6))+IF(B6=2050,SUMIFS(storage_capacity_2040,onshore_or_offshore,"Onshore storage",operational_category_high,2,onshore_nuts1,A6))+IF(B6=2050,SUMIFS(storage_capacity_2050,onshore_or_offshore,"Onshore storage",operational_category_high,3,onshore_nuts1,A6)) -> 0 | F6: Mtpa
A7: DK | B7: 2040 | C7: =SUMIFS(storage_capacity_2030,onshore_or_offshore,"Onshore storage",operational_category_low,1,onshore_nuts1,A7)+IF(B7=2040,SUMIFS(storage_capacity_2040,onshore_or_offshore,"Onshore storage",operational_category_low,2,onshore_nuts1,A7))+IF(B7=2050,SUMIFS(storage_capacity_2040,onshore_or_offshore,"Onshore storage",operational_category_low,2,onshore_nuts1,A7))+IF(B7=2050,SUMIFS(storage_capacity_2050,onshore_or_offshore,"Onshore storage",operational_category_low,3,onshore_nuts1,A7)) -> 0 | D7: =SUMIFS(storage_capacity_2030,onshore_or_offshore,"Onshore storage",operational_category_medium,1,onshore_nuts1,A7)+IF(B7=2040,SUMIFS(storage_capacity_2040,onshore_or_offshore,"Onshore storage",operational_category_medium,2,onshore_nuts1,A7))+IF(B7=2050,SUMIFS(storage_capacity_2040,onshore_or_offshore,"Onshore storage",operational_category_medium,2,onshore_nuts1,A7))+IF(B7=2050,SUMIFS(storage_capacity_2050,onshore_or_offshore,"Onshore storage",operational_category_medium,3,onshore_nuts1,A7)) -> 0 | E7: =SUMIFS(storage_capacity_2030,onshore_or_offshore,"Onshore storage",operational_category_high,1,onshore_nuts1,A7)+IF(B7=2040,SUMIFS(storage_capacity_2040,onshore_or_offshore,"Onshore storage",operational_category_high,2,onshore_nuts1,A7))+IF(B7=2050,SUMIFS(storage_capacity_2040,onshore_or_offshore,"Onshore storage",operational_category_high,2,onshore_nuts1,A7))+IF(B7=2050,SUMIFS(storage_capacity_2050,onshore_or_offshore,"Onshore storage",operational_category_high,3,onshore_nuts1,A7)) -> 25.5 | F7: Mtpa
A8: FR | B8: 2040 | C8: =SUMIFS(storage_capacity_2030,onshore_or_offshore,"Onshore storage",operational_category_low,1,onshore_nuts1,A8)+IF(B8=2040,SUMIFS(storage_capacity_2040,onshore_or_offshore,"Onshore storage",operational_category_low,2,onshore_nuts1,A8))+IF(B8=2050,SUMIFS(storage_capacity_2040,onshore_or_offshore,"Onshore storage",operational_category_low,2,onshore_nuts1,A8))+IF(B8=2050,SUMIFS(storage_capacity_2050,onshore_or_offshore,"Onshore storage",operational_category_low,3,onshore_nuts1,A8)) -> 0 | D8: =SUMIFS(storage_capacity_2030,onshore_or_offshore,"Onshore storage",operational_category_medium,1,onshore_nuts1,A8)+IF(B8=2040,SUMIFS(storage_capacity_2040,onshore_or_offshore,"Onshore storage",operational_category_medium,2,onshore_nuts1,A8))+IF(B8=2050,SUMIFS(storage_capacity_2040,onshore_or_offshore,"Onshore storage",operational_category_medium,2,onshore_nuts1,A8))+IF(B8=2050,SUMIFS(storage_capacity_2050,onshore_or_offshore,"Onshore storage",operational_category_medium,3,onshore_nuts1,A8)) -> 0 | E8: =SUMIFS(storage_capacity_2030,onshore_or_offshore,"Onshore storage",operational_category_high,1,onshore_nuts1,A8)+IF(B8=2040,SUMIFS(storage_capacity_2040,onshore_or_offshore,"Onshore storage",operational_category_high,2,onshore_nuts1,A8))+IF(B8=2050,SUMIFS(storage_capacity_2040,onshore_or_offshore,"Onshore storage",operational_category_high,2,onshore_nuts1,A8))+IF(B8=2050,SUMIFS(storage_capacity_2050,onshore_or_offshore,"Onshore storage",operational_category_high,3,onshore_nuts1,A8)) -> 2.5 | F8: Mtpa
A9: RO | B9: 2040 | C9: =SUMIFS(storage_capacity_2030,onshore_or_offshore,"Onshore storage",operational_category_low,1,onshore_nuts1,A9)+IF(B9=2040,SUMIFS(storage_capacity_2040,onshore_or_offshore,"Onshore storage",operational_category_low,2,onshore_nuts1,A9))+IF(B9=2050,SUMIFS(storage_capacity_2040,onshore_or_offshore,"Onshore storage",operational_category_low,2,onshore_nuts1,A9))+IF(B9=2050,SUMIFS(storage_capacity_2050,onshore_or_offshore,"Onshore storage",operational_category_low,3,onshore_nuts1,A9)) -> 0 | D9: =SUMIFS(storage_capacity_2030,onshore_or_offshore,"Onshore storage",operational_category_medium,1,onshore_nuts1,A9)+IF(B9=2040,SUMIFS(storage_capacity_2040,onshore_or_offshore,"Onshore storage",operational_category_medium,2,onshore_nuts1,A9))+IF(B9=2050,SUMIFS(storage_capacity_2040,onshore_or_offshore,"Onshore storage",operational_category_medium,2,onshore_nuts1,A9))+IF(B9=2050,SUMIFS(storage_capacity_2050,onshore_or_offshore,"Onshore storage",operational_category_medium,3,onshore_nuts1,A9)) -> 0 | E9: =SUMIFS(storage_capacity_2030,onshore_or_offshore,"Onshore storage",operational_category_high,1,onshore_nuts1,A9)+IF(B9=2040,SUMIFS(storage_capacity_2040,onshore_or_offshore,"Onshore storage",operational_category_high,2,onshore_nuts1,A9))+IF(B9=2050,SUMIFS(storage_capacity_2040,onshore_or_offshore,"Onshore storage",operational_category_high,2,onshore_nuts1,A9))+IF(B9=2050,SUMIFS(storage_capacity_2050,onshore_or_offshore,"Onshore storage",operational_category_high,3,onshore_nuts1,A9)) -> 0.6 | F9: Mtpa
A10: HR | B10: 2040 | C10: =SUMIFS(storage_capacity_2030,onshore_or_offshore,"Onshore storage",operational_category_low,1,onshore_nuts1,A10)+IF(B10=2040,SUMIFS(storage_capacity_2040,onshore_or_offshore,"Onshore storage",operational_category_low,2,onshore_nuts1,A10))+IF(B10=2050,SUMIFS(storage_capacity_2040,onshore_or_offshore,"Onshore storage",operational_category_low,2,onshore_nuts1,A10))+IF(B10=2050,SUMIFS(storage_capacity_2050,onshore_or_offshore,"Onshore storage",operational_category_low,3,onshore_nuts1,A10)) -> 0 | D10: =SUMIFS(storage_capacity_2030,onshore_or_offshore,"Onshore storage",operational_category_medium,1,onshore_nuts1,A10)+IF(B10=2040,SUMIFS(storage_capacity_2040,onshore_or_offshore,"Onshore storage",operational_category_medium,2,onshore_nuts1,A10))+IF(B10=2050,SUMIFS(storage_capacity_2040,onshore_or_offshore,"Onshore storage",operational_category_medium,2,onshore_nuts1,A10))+IF(B10=2050,SUMIFS(storage_capacity_2050,onshore_or_offshore,"Onshore storage",operational_category_medium,3,onshore_nuts1,A10)) -> 0 | E10: =SUMIFS(storage_capacity_2030,onshore_or_offshore,"Onshore storage",operational_category_high,1,onshore_nuts1,A10)+IF(B10=2040,SUMIFS(storage_capacity_2040,onshore_or_offshore,"Onshore storage",operational_category_high,2,onshore_nuts1,A10))+IF(B10=2050,SUMIFS(storage_capacity_2040,onshore_or_offshore,"Onshore storage",operational_category_high,2,onshore_nuts1,A10))+IF(B10=2050,SUMIFS(storage_capacity_2050,onshore_or_offshore,"Onshore storage",operational_category_high,3,onshore_nuts1,A10)) -> 1.5 | F10: Mtpa
A11: BG | B11: 2040 | C11: =SUMIFS(storage_capacity_2030,onshore_or_offshore,"Onshore storage",operational_category_low,1,onshore_nuts1,A11)+IF(B11=2040,SUMIFS(storage_capacity_2040,onshore_or_offshore,"Onshore storage",operational_category_low,2,onshore_nuts1,A11))+IF(B11=2050,SUMIFS(storage_capacity_2040,onshore_or_offshore,"Onshore storage",operational_category_low,2,onshore_nuts1,A11))+IF(B11=2050,SUMIFS(storage_capacity_2050,onshore_or_offshore,"Onshore storage",operational_category_low,3,onshore_nuts1,A11)) -> 0 | D11: =SUMIFS(storage_capacity_2030,onshore_or_offshore,"Onshore storage",operational_category_medium,1,onshore_nuts1,A11)+IF(B11=2040,SUMIFS(storage_capacity_2040,onshore_or_offshore,"Onshore storage",operational_category_medium,2,onshore_nuts1,A11))+IF(B11=2050,SUMIFS(storage_capacity_2040,onshore_or_offshore,"Onshore storage",operational_category_medium,2,onshore_nuts1,A11))+IF(B11=2050,SUMIFS(storage_capacity_2050,onshore_or_offshore,"Onshore storage",operational_category_medium,3,onshore_nuts1,A11)) -> 0 | E11: =SUMIFS(storage_capacity_2030,onshore_or_offshore,"Onshore storage",operational_category_high,1,onshore_nuts1,A11)+IF(B11=2040,SUMIFS(storage_capacity_2040,onshore_or_offshore,"Onshore storage",operational_category_high,2,onshore_nuts1,A11))+IF(B11=2050,SUMIFS(storage_capacity_2040,onshore_or_offshore,"Onshore storage",operational_category_high,2,onshore_nuts1,A11))+IF(B11=2050,SUMIFS(storage_capacity_2050,onshore_or_offshore,"Onshore storage",operational_category_high,3,onshore_nuts1,A11)) -> 1.5 | F11: Mtpa
A12: DK | B12: 2050 | C12: =SUMIFS(storage_capacity_2030,onshore_or_offshore,"Onshore storage",operational_category_low,1,onshore_nuts1,A12)+IF(B12=2040,SUMIFS(storage_capacity_2040,onshore_or_offshore,"Onshore storage",operational_category_low,2,onshore_nuts1,A12))+IF(B12=2050,SUMIFS(storage_capacity_2040,onshore_or_offshore,"Onshore storage",operational_category_low,2,onshore_nuts1,A12))+IF(B12=2050,SUMIFS(storage_capacity_2050,onshore_or_offshore,"Onshore storage",operational_category_low,3,onshore_nuts1,A12)) -> 0 | D12: =SUMIFS(storage_capacity_2030,onshore_or_offshore,"Onshore storage",operational_category_medium,1,onshore_nuts1,A12)+IF(B12=2040,SUMIFS(storage_capacity_2040,onshore_or_offshore,"Onshore storage",operational_category_medium,2,onshore_nuts1,A12))+IF(B12=2050,SUMIFS(storage_capacity_2040,onshore_or_offshore,"Onshore storage",operational_category_medium,2,onshore_nuts1,A12))+IF(B12=2050,SUMIFS(storage_capacity_2050,onshore_or_offshore,"Onshore storage",operational_category_medium,3,onshore_nuts1,A12)) -> 25.5 | E12: =SUMIFS(storage_capacity_2030,onshore_or_offshore,"Onshore storage",operational_category_high,1,onshore_nuts1,A12)+IF(B12=2040,SUMIFS(storage_capacity_2040,onshore_or_offshore,"Onshore storage",operational_category_high,2,onshore_nuts1,A12))+IF(B12=2050,SUMIFS(storage_capacity_2040,onshore_or_offshore,"Onshore storage",operational_category_high,2,onshore_nuts1,A12))+IF(B12=2050,SUMIFS(storage_capacity_2050,onshore_or_offshore,"Onshore storage",operational_category_high,3,onshore_nuts1,A12)) -> 25.5 | F12: Mtpa
A13: FR | B13: 2050 | C13: =SUMIFS(storage_capacity_2030,onshore_or_offshore,"Onshore storage",operational_category_low,1,onshore_nuts1,A13)+IF(B13=2040,SUMIFS(storage_capacity_2040,onshore_or_offshore,"Onshore storage",operational_category_low,2,onshore_nuts1,A13))+IF(B13=2050,SUMIFS(storage_capacity_2040,onshore_or_offshore,"Onshore storage",operational_category_low,2,onshore_nuts1,A13))+IF(B13=2050,SUMIFS(storage_capacity_2050,onshore_or_offshore,"Onshore storage",operational_category_low,3,onshore_nuts1,A13)) -> 0 | D13: =SUMIFS(storage_capacity_2030,onshore_or_offshore,"Onshore storage",operational_category_medium,1,onshore_nuts1,A13)+IF(B13=2040,SUMIFS(storage_capacity_2040,onshore_or_offshore,"Onshore storage",operational_category_medium,2,onshore_nuts1,A13))+IF(B13=2050,SUMIFS(storage_capacity_2040,onshore_or_offshore,"Onshore storage",operational_category_medium,2,onshore_nuts1,A13))+IF(B13=2050,SUMIFS(storage_capacity_2050,onshore_or_offshore,"Onshore storage",operational_category_medium,3,onshore_nuts1,A13)) -> 2.5 | E13: =SUMIFS(storage_capacity_2030,onshore_or_offshore,"Onshore storage",operational_category_high,1,onshore_nuts1,A13)+IF(B13=2040,SUMIFS(storage_capacity_2040,onshore_or_offshore,"Onshore storage",operational_category_high,2,onshore_nuts1,A13))+IF(B13=2050,SUMIFS(storage_capacity_2040,onshore_or_offshore,"Onshore storage",operational_category_high,2,onshore_nuts1,A13))+IF(B13=2050,SUMIFS(storage_capacity_2050,onshore_or_offshore,"Onshore storage",operational_category_high,3,onshore_nuts1,A13)) -> 2.5 | F13: Mtpa
... A16: BG | B16: 2050 | C16: =SUMIFS(storage_capacity_2030,onshore_or_offshore,"Onshore storage",operational_category_low,1,onshore_nuts1,A16)+IF(B16=2040,SUMIFS(storage_capacity_2040,onshore_or_offshore,"Onshore storage",operational_category_low,2,onshore_nuts1,A16))+IF(B16=2050,SUMIFS(storage_capacity_2040,onshore_or_offshore,"Onshore storage",operational_category_low,2,onshore_nuts1,A16))+IF(B16=2050,SUMIFS(storage_capacity_2050,onshore_or_offshore,"Onshore storage",operational_category_low,3,onshore_nuts1,A16)) -> 0 | D16: =SUMIFS(storage_capacity_2030,onshore_or_offshore,"Onshore storage",operational_category_medium,1,onshore_nuts1,A16)+IF(B16=2040,SUMIFS(storage_capacity_2040,onshore_or_offshore,"Onshore storage",operational_category_medium,2,onshore_nuts1,A16))+IF(B16=2050,SUMIFS(storage_capacity_2040,onshore_or_offshore,"Onshore storage",operational_category_medium,2,onshore_nuts1,A16))+IF(B16=2050,SUMIFS(storage_capacity_2050,onshore_or_offshore,"Onshore storage",operational_category_medium,3,onshore_nuts1,A16)) -> 1.5 | E16: =SUMIFS(storage_capacity_2030,onshore_or_offshore,"Onshore storage",operational_category_high,1,onshore_nuts1,A16)+IF(B16=2040,SUMIFS(storage_capacity_2040,onshore_or_offshore,"Onshore storage",operational_category_high,2,onshore_nuts1,A16))+IF(B16=2050,SUMIFS(storage_capacity_2040,onshore_or_offshore,"Onshore storage",operational_category_high,2,onshore_nuts1,A16))+IF(B16=2050,SUMIFS(storage_capacity_2050,onshore_or_offshore,"Onshore storage",operational_category_high,3,onshore_nuts1,A16)) -> 1.5 | F16: Mtpa

Sheet Offshore_storage_potentials
A1: #offshore_region | B1: country | C1: OFF3 | D1: year | E1: low | F1: medium | G1: high | H1: unit
A2: =VLOOKUP($C2,offshore_nodes!$A$2:$C$20,3,FALSE) -> 1 | B2: =VLOOKUP(C2,Table2[[OFF3]:[PECD]],2,FALSE) -> DE | C2: NSDE011 | D2: 2030 | E2: =SUMIFS(storage_capacity_2030,onshore_or_offshore,"Offshore storage",operational_category_low,1,offshore_region,C2)+IF(D2=2040,SUMIFS(storage_capacity_2040,onshore_or_offshore,"Offshore storage",operational_category_low,2,offshore_region,C2))+IF(D2=2050,SUMIFS(storage_capacity_2040,onshore_or_offshore,"Offshore storage",operational_category_low,2,offshore_region,C2))+IF(D2=2050,SUMIFS(storage_capacity_2050,onshore_or_offshore,"Offshore storage",operational_category_low,3,offshore_region,C2)) -> 0 | F2: =SUMIFS(storage_capacity_2030,onshore_or_offshore,"Offshore storage",operational_category_medium,1,offshore_region,C2)+IF(D2=2040,SUMIFS(storage_capacity_2040,onshore_or_offshore,"Offshore storage",operational_category_medium,2,offshore_region,C2))+IF(D2=2050,SUMIFS(storage_capacity_2040,onshore_or_offshore,"Offshore storage",operational_category_medium,2,offshore_region,C2))+IF(D2=2050,SUMIFS(storage_capacity_2050,onshore_or_offshore,"Offshore storage",operational_category_medium,3,offshore_region,C2)) -> 0 | G2: =SUMIFS(storage_capacity_2030,onshore_or_offshore,"Offshore storage",operational_category_high,1,offshore_region,C2)+IF(D2=2040,SUMIFS(storage_capacity_2040,onshore_or_offshore,"Offshore storage",operational_category_high,2,offshore_region,C2))+IF(D2=2050,SUMIFS(storage_capacity_2040,onshore_or_offshore,"Offshore storage",operational_category_high,2,offshore_region,C2))+IF(D2=2050,SUMIFS(storage_capacity_2050,onshore_or_offshore,"Offshore storage",operational_category_high,3,offshore_region,C2)) -> 0 | H2: Mtpa
A3: =VLOOKUP($C3,offshore_nodes!$A$2:$C$20,3,FALSE) -> 1 | B3: =VLOOKUP(C3,Table2[[OFF3]:[PECD]],2,FALSE) -> DK | C3: NSDKW12 | D3: 2030 | E3: =SUMIFS(storage_capacity_2030,onshore_or_offshore,"Offshore storage",operational_category_low,1,offshore_region,C3)+IF(D3=2040,SUMIFS(storage_capacity_2040,onshore_or_offshore,"Offshore storage",operational_category_low,2,offshore_region,C3))+IF(D3=2050,SUMIFS(storage_capacity_2040,onshore_or_offshore,"Offshore storage",operational_category_low,2,offshore_region,C3))+IF(D3=2050,SUMIFS(storage_capacity_2050,onshore_or_offshore,"Offshore storage",operational_category_low,3,offshore_region,C3)) -> 11 | F3: =SUMIFS(storage_capacity_2030,onshore_or_offshore,"Offshore storage",operational_category_medium,1,offshore_region,C3)+IF(D3=2040,SUMIFS(storage_capacity_2040,onshore_or_offshore,"Offshore storage",operational_category_medium,2,offshore_region,C3))+IF(D3=2050,SUMIFS(storage_capacity_2040,onshore_or_offshore,"Offshore storage",operational_category_medium,2,offshore_region,C3))+IF(D3=2050,SUMIFS(storage_capacity_2050,onshore_or_offshore,"Offshore storage",operational_category_medium,3,offshore_region,C3)) -> 11 | G3: =SUMIFS(storage_capacity_2030,onshore_or_offshore,"Offshore storage",operational_category_high,1,offshore_region,C3)+IF(D3=2040,SUMIFS(storage_capacity_2040,onshore_or_offshore,"Offshore storage",operational_category_high,2,offshore_region,C3))+IF(D3=2050,SUMIFS(storage_capacity_2040,onshore_or_offshore,"Offshore storage",operational_category_high,2,offshore_region,C3))+IF(D3=2050,SUMIFS(storage_capacity_2050,onshore_or_offshore,"Offshore storage",operational_category_high,3,offshore_region,C3)) -> 11 | H3: Mtpa
A4: =VLOOKUP($C4,offshore_nodes!$A$2:$C$20,3,FALSE) -> 1 | B4: =VLOOKUP(C4,Table2[[OFF3]:[PECD]],2,FALSE) -> ES | C4: WMES06 | D4: 2030 | E4: =SUMIFS(storage_capacity_2030,onshore_or_offshore,"Offshore storage",operational_category_low,1,offshore_region,C4)+IF(D4=2040,SUMIFS(storage_capacity_2040,onshore_or_offshore,"Offshore storage",operational_category_low,2,offshore_region,C4))+IF(D4=2050,SUMIFS(storage_capacity_2040,onshore_or_offshore,"Offshore storage",operational_category_low,2,offshore_region,C4))+IF(D4=2050,SUMIFS(storage_capacity_2050,onshore_or_offshore,"Offshore storage",operational_category_low,3,offshore_region,C4)) -> 0 | F4: =SUMIFS(storage_capacity_2030,onshore_or_offshore,"Offshore storage",operational_category_medium,1,offshore_region,C4)+IF(D4=2040,SUMIFS(storage_capacity_2040,onshore_or_offshore,"Offshore storage",operational_category_medium,2,offshore_region,C4))+IF(D4=2050,SUMIFS(storage_capacity_2040,onshore_or_offshore,"Offshore storage",operational_category_medium,2,offshore_region,C4))+IF(D4=2050,SUMIFS(storage_capacity_2050,onshore_or_offshore,"Offshore storage",operational_category_medium,3,offshore_region,C4)) -> 0 | G4: =SUMIFS(storage_capacity_2030,onshore_or_offshore,"Offshore storage",operational_category_high,1,offshore_region,C4)+IF(D4=2040,SUMIFS(storage_capacity_2040,onshore_or_offshore,"Offshore storage",operational_category_high,2,offshore_region,C4))+IF(D4=2050,SUMIFS(storage_capacity_2040,onshore_or_offshore,"Offshore storage",operational_category_high,2,offshore_region,C4))+IF(D4=2050,SUMIFS(storage_capacity_2050,onshore_or_offshore,"Offshore storage",operational_category_high,3,offshore_region,C4)) -> 0 | H4: Mtpa
A5: =VLOOKUP($C5,offshore_nodes!$A$2:$C$20,3,FALSE) -> 1 | B5: =VLOOKUP(C5,Table2[[OFF3]:[PECD]],2,FALSE) -> GR | C5: EMGR02 | D5: 2030 | E5: =SUMIFS(storage_capacity_2030,onshore_or_offshore,"Offshore storage",operational_category_low,1,offshore_region,C5)+IF(D5=2040,SUMIFS(storage_capacity_2040,onshore_or_offshore,"Offshore storage",operational_category_low,2,offshore_region,C5))+IF(D5=2050,SUMIFS(storage_capacity_2040,onshore_or_offshore,"Offshore storage",operational_category_low,2,offshore_region,C5))+IF(D5=2050,SUMIFS(storage_capacity_2050,onshore_or_offshore,"Offshore storage",operational_category_low,3,offshore_region,C5)) -> 2.5 | F5: =SUMIFS(storage_capacity_2030,onshore_or_offshore,"Offshore storage",operational_category_medium,1,offshore_region,C5)+IF(D5=2040,SUMIFS(storage_capacity_2040,onshore_or_offshore,"Offshore storage",operational_category_medium,2,offshore_region,C5))+IF(D5=2050,SUMIFS(storage_capacity_2040,onshore_or_offshore,"Offshore storage",operational_category_medium,2,offshore_region,C5))+IF(D5=2050,SUMIFS(storage_capacity_2050,onshore_or_offshore,"Offshore storage",operational_category_medium,3,offshore_region,C5)) -> 2.5 | G5: =SUMIFS(storage_capacity_2030,onshore_or_offshore,"Offshore storage",operational_category_high,1,offshore_region,C5)+IF(D5=2040,SUMIFS(storage_capacity_2040,onshore_or_offshore,"Offshore storage",operational_category_high,2,offshore_region,C5))+IF(D5=2050,SUMIFS(storage_capacity_2040,onshore_or_offshore,"Offshore storage",operational_category_high,2,offshore_region,C5))+IF(D5=2050,SUMIFS(storage_capacity_2050,onshore_or_offshore,"Offshore storage",operational_category_high,3,offshore_region,C5)) -> 2.5 | H5: Mtpa
A6: =VLOOKUP($C6,offshore_nodes!$A$2:$C$20,3,FALSE) -> 1 | B6: =VLOOKUP(C6,Table2[[OFF3]:[PECD]],2,FALSE) -> IE | C6: ATIE03 | D6: 2030 | E6: =SUMIFS(storage_capacity_2030,onshore_or_offshore,"Offshore storage",operational_category_low,1,offshore_region,C6)+IF(D6=2040,SUMIFS(storage_capacity_2040,onshore_or_offshore,"Offshore storage",operational_category_low,2,offshore_region,C6))+IF(D6=2050,SUMIFS(storage_capacity_2040,onshore_or_offshore,"Offshore storage",operational_category_low,2,offshore_region,C6))+IF(D6=2050,SUMIFS(storage_capacity_2050,onshore_or_offshore,"Offshore storage",operational_category_low,3,offshore_region,C6)) -> 0 | F6: =SUMIFS(storage_capacity_2030,onshore_or_offshore,"Offshore storage",operational_category_medium,1,offshore_region,C6)+IF(D6=2040,SUMIFS(storage_capacity_2040,onshore_or_offshore,"Offshore storage",operational_category_medium,2,offshore_region,C6))+IF(D6=2050,SUMIFS(storage_capacity_2040,onshore_or_offshore,"Offshore storage",operational_category_medium,2,offshore_region,C6))+IF(D6=2050,SUMIFS(storage_capacity_2050,onshore_or_offshore,"Offshore storage",operational_category_medium,3,offshore_region,C6)) -> 0 | G6: =SUMIFS(storage_capacity_2030,onshore_or_offshore,"Offshore storage",operational_category_high,1,offshore_region,C6)+IF(D6=2040,SUMIFS(storage_capacity_2040,onshore_or_offshore,"Offshore storage",operational_category_high,2,offshore_region,C6))+IF(D6=2050,SUMIFS(storage_capacity_2040,onshore_or_offshore,"Offshore storage",operational_category_high,2,offshore_region,C6))+IF(D6=2050,SUMIFS(storage_capacity_2050,onshore_or_offshore,"Offshore storage",operational_category_high,3,offshore_region,C6)) -> 0 | H6: Mtpa
A7: =VLOOKUP($C7,offshore_nodes!$A$2:$C$20,3,FALSE) -> 1 | B7: =VLOOKUP(C7,Table2[[OFF3]:[PECD]],2,FALSE) -> IT | C7: WMITN1 | D7: 2030 | E7: =SUMIFS(storage_capacity_2030,onshore_or_offshore,"Offshore storage",operational_category_low,1,offshore_region,C7)+IF(D7=2040,SUMIFS(storage_capacity_2040,onshore_or_offshore,"Offshore storage",operational_category_low,2,offshore_region,C7))+IF(D7=2050,SUMIFS(storage_capacity_2040,onshore_or_offshore,"Offshore storage",operational_category_low,2,offshore_region,C7))+IF(D7=2050,SUMIFS(storage_capacity_2050,onshore_or_offshore,"Offshore storage",operational_category_low,3,offshore_region,C7)) -> 4 | F7: =SUMIFS(storage_capacity_2030,onshore_or_offshore,"Offshore storage",operational_category_medium,1,offshore_region,C7)+IF(D7=2040,SUMIFS(storage_capacity_2040,onshore_or_offshore,"Offshore storage",operational_category_medium,2,offshore_region,C7))+IF(D7=2050,SUMIFS(storage_capacity_2040,onshore_or_offshore,"Offshore storage",operational_category_medium,2,offshore_region,C7))+IF(D7=2050,SUMIFS(storage_capacity_2050,onshore_or_offshore,"Offshore storage",operational_category_medium,3,offshore_region,C7)) -> 4 | G7: =SUMIFS(storage_capacity_2030,onshore_or_offshore,"Offshore storage",operational_category_high,1,offshore_region,C7)+IF(D7=2040,SUMIFS(storage_capacity_2040,onshore_or_offshore,"Offshore storage",operational_category_high,2,offshore_region,C7))+IF(D7=2050,SUMIFS(storage_capacity_2040,onshore_or_offshore,"Offshore storage",operational_category_high,2,offshore_region,C7))+IF(D7=2050,SUMIFS(storage_capacity_2050,onshore_or_offshore,"Offshore storage",operational_category_high,3,offshore_region,C7)) -> 4 | H7: Mtpa
A8: =VLOOKUP($C8,offshore_nodes!$A$2:$C$20,3,FALSE) -> 1 | B8: =VLOOKUP(C8,Table2[[OFF3]:[PECD]],2,FALSE) -> NL | C8: NSNL012 | D8: 2030 | E8: =SUMIFS(storage_capacity_2030,onshore_or_offshore,"Offshore storage",operational_category_low,1,offshore_region,C8)+IF(D8=2040,SUMIFS(storage_capacity_2040,onshore_or_offshore,"Offshore storage",operational_category_low,2,offshore_region,C8))+IF(D8=2050,SUMIFS(storage_capacity_2040,onshore_or_offshore,"Offshore storage",operational_category_low,2,offshore_region,C8))+IF(D8=2050,SUMIFS(storage_capacity_2050,onshore_or_offshore,"Offshore storage",operational_category_low,3,offshore_region,C8)) -> 0 | F8: =SUMIFS(storage_capacity_2030,onshore_or_offshore,"Offshore storage",operational_category_medium,1,offshore_region,C8)+IF(D8=2040,SUMIFS(storage_capacity_2040,onshore_or_offshore,"Offshore storage",operational_category_medium,2,offshore_region,C8))+IF(D8=2050,SUMIFS(storage_capacity_2040,onshore_or_offshore,"Offshore storage",operational_category_medium,2,offshore_region,C8))+IF(D8=2050,SUMIFS(storage_capacity_2050,onshore_or_offshore,"Offshore storage",operational_category_medium,3,offshore_region,C8)) -> 0 | G8: =SUMIFS(storage_capacity_2030,onshore_or_offshore,"Offshore storage",operational_category_high,1,offshore_region,C8)+IF(D8=2040,SUMIFS(storage_capacity_2040,onshore_or_offshore,"Offshore storage",operational_category_high,2,offshore_region,C8))+IF(D8=2050,SUMIFS(storage_capacity_2040,onshore_or_offshore,"Offshore storage",operational_category_high,2,offshore_region,C8))+IF(D8=2050,SUMIFS(storage_capacity_2050,onshore_or_offshore,"Offshore storage",operational_category_high,3,offshore_region,C8)) -> 0 | H8: Mtpa
A9: =VLOOKUP($C9,offshore_nodes!$A$2:$C$20,3,FALSE) -> 2 | B9: =VLOOKUP(C9,Table2[[OFF3]:[PECD]],2,FALSE) -> NL | C9: NSNL031 | D9: 2030 | E9: =SUMIFS(storage_capacity_2030,onshore_or_offshore,"Offshore storage",operational_category_low,1,offshore_region,C9)+IF(D9=2040,SUMIFS(storage_capacity_2040,onshore_or_offshore,"Offshore storage",operational_category_low,2,offshore_region,C9))+IF(D9=2050,SUMIFS(storage_capacity_2040,onshore_or_offshore,"Offshore storage",operational_category_low,2,offshore_region,C9))+IF(D9=2050,SUMIFS(storage_capacity_2050,onshore_or_offshore,"Offshore storage",operational_category_low,3,offshore_region,C9)) -> 2.5 | F9: =SUMIFS(storage_capacity_2030,onshore_or_offshore,"Offshore storage",operational_category_medium,1,offshore_region,C9)+IF(D9=2040,SUMIFS(storage_capacity_2040,onshore_or_offshore,"Offshore storage",operational_category_medium,2,offshore_region,C9))+IF(D9=2050,SUMIFS(storage_capacity_2040,onshore_or_offshore,"Offshore storage",operational_category_medium,2,offshore_region,C9))+IF(D9=2050,SUMIFS(storage_capacity_2050,onshore_or_offshore,"Offshore storage",operational_category_medium,3,offshore_region,C9)) -> 2.5 | G9: =SUMIFS(storage_capacity_2030,onshore_or_offshore,"Offshore storage",operational_category_high,1,offshore_region,C9)+IF(D9=2040,SUMIFS(storage_capacity_2040,onshore_or_offshore,"Offshore storage",operational_category_high,2,offshore_region,C9))+IF(D9=2050,SUMIFS(storage_capacity_2040,onshore_or_offshore,"Offshore storage",operational_category_high,2,offshore_region,C9))+IF(D9=2050,SUMIFS(storage_capacity_2050,onshore_or_offshore,"Offshore storage",operational_category_high,3,offshore_region,C9)) -> 2.5 | H9: Mtpa
A10: =VLOOKUP($C10,offshore_nodes!$A$2:$C$20,3,FALSE) -> 1 | B10: =VLOOKUP(C10,Table2[[OFF3]:[PECD]],2,FALSE) -> NO | C10: ASNON1 | D10: 2030 | E10: =SUMIFS(storage_capacity_2030,onshore_or_offshore,"Offshore storage",operational_category_low,1,offshore_region,C10)+IF(D10=2040,SUMIFS(storage_capacity_2040,onshore_or_offshore,"Offshore storage",operational_category_low,2,offshore_region,C10))+IF(D10=2050,SUMIFS(storage_capacity_2040,onshore_or_offshore,"Offshore storage",operational_category_low,2,offshore_region,C10))+IF(D10=2050,SUMIFS(storage_capacity_2050,onshore_or_offshore,"Offshore storage",operational_category_low,3,offshore_region,C10)) -> 0.7 | F10: =SUMIFS(storage_capacity_2030,onshore_or_offshore,"Offshore storage",operational_category_medium,1,offshore_region,C10)+IF(D10=2040,SUMIFS(storage_capacity_2040,onshore_or_offshore,"Offshore storage",operational_category_medium,2,offshore_region,C10))+IF(D10=2050,SUMIFS(storage_capacity_2040,onshore_or_offshore,"Offshore storage",operational_category_medium,2,offshore_region,C10))+IF(D10=2050,SUMIFS(storage_capacity_2050,onshore_or_offshore,"Offshore storage",operational_category_medium,3,offshore_region,C10)) -> 0.7 | G10: =SUMIFS(storage_capacity_2030,onshore_or_offshore,"Offshore storage",operational_category_high,1,offshore_region,C10)+IF(D10=2040,SUMIFS(storage_capacity_2040,onshore_or_offshore,"Offshore storage",operational_category_high,2,offshore_region,C10))+IF(D10=2050,SUMIFS(storage_capacity_2040,onshore_or_offshore,"Offshore storage",operational_category_high,2,offshore_region,C10))+IF(D10=2050,SUMIFS(storage_capacity_2050,onshore_or_offshore,"Offshore storage",operational_category_high,3,offshore_region,C10)) -> 0.7 | H10: Mtpa
A11: =VLOOKUP($C11,offshore_nodes!$A$2:$C$20,3,FALSE) -> 2 | B11: =VLOOKUP(C11,Table2[[OFF3]:[PECD]],2,FALSE) -> NO | C11: ASNOS3 | D11: 2030 | E11: =SUMIFS(storage_capacity_2030,onshore_or_offshore,"Offshore storage",operational_category_low,1,offshore_region,C11)+IF(D11=2040,SUMIFS(storage_capacity_2040,onshore_or_offshore,"Offshore storage",operational_category_low,2,offshore_region,C11))+IF(D11=2050,SUMIFS(storage_capacity_2040,onshore_or_offshore,"Offshore storage",operational_category_low,2,offshore_region,C11))+IF(D11=2050,SUMIFS(storage_capacity_2050,onshore_or_offshore,"Offshore storage",operational_category_low,3,offshore_region,C11)) -> 5.2 | F11: =SUMIFS(storage_capacity_2030,onshore_or_offshore,"Offshore storage",operational_category_medium,1,offshore_region,C11)+IF(D11=2040,SUMIFS(storage_capacity_2040,onshore_or_offshore,"Offshore storage",operational_category_medium,2,offshore_region,C11))+IF(D11=2050,SUMIFS(storage_capacity_2040,onshore_or_offshore,"Offshore storage",operational_category_medium,2,offshore_region,C11))+IF(D11=2050,SUMIFS(storage_capacity_2050,onshore_or_offshore,"Offshore storage",operational_category_medium,3,offshore_region,C11)) -> 5.2 | G11: =SUMIFS(storage_capacity_2030,onshore_or_offshore,"Offshore storage",operational_category_high,1,offshore_region,C11)+IF(D11=2040,SUMIFS(storage_capacity_2040,onshore_or_offshore,"Offshore storage",operational_category_high,2,offshore_region,C11))+IF(D11=2050,SUMIFS(storage_capacity_2040,onshore_or_offshore,"Offshore storage",operational_category_high,2,offshore_region,C11))+IF(D11=2050,SUMIFS(storage_capacity_2050,onshore_or_offshore,"Offshore storage",operational_category_high,3,offshore_region,C11)) -> 5.2 | H11: Mtpa
A12: =VLOOKUP($C12,offshore_nodes!$A$2:$C$20,3,FALSE) -> 3 | B12: =VLOOKUP(C12,Table2[[OFF3]:[PECD]],2,FALSE) -> NO | C12: NSNOS22 | D12: 2030 | E12: =SUMIFS(storage_capacity_2030,onshore_or_offshore,"Offshore storage",operational_category_low,1,offshore_region,C12)+IF(D12=2040,SUMIFS(storage_capacity_2040,onshore_or_offshore,"Offshore storage",operational_category_low,2,offshore_region,C12))+IF(D12=2050,SUMIFS(storage_capacity_2040,onshore_or_offshore,"Offshore storage",operational_category_low,2,offshore_region,C12))+IF(D12=2050,SUMIFS(storage_capacity_2050,onshore_or_offshore,"Offshore storage",operational_category_low,3,offshore_region,C12)) -> 1 | F12: =SUMIFS(storage_capacity_2030,onshore_or_offshore,"Offshore storage",operational_category_medium,1,offshore_region,C12)+IF(D12=2040,SUMIFS(storage_capacity_2040,onshore_or_offshore,"Offshore storage",operational_category_medium,2,offshore_region,C12))+IF(D12=2050,SUMIFS(storage_capacity_2040,onshore_or_offshore,"Offshore storage",operational_category_medium,2,offshore_region,C12))+IF(D12=2050,SUMIFS(storage_capacity_2050,onshore_or_offshore,"Offshore storage",operational_category_medium,3,offshore_region,C12)) -> 1 | G12: =SUMIFS(storage_capacity_2030,onshore_or_offshore,"Offshore storage",operational_category_high,1,offshore_region,C12)+IF(D12=2040,SUMIFS(storage_capacity_2040,onshore_or_offshore,"Offshore storage",operational_category_high,2,offshore_region,C12))+IF(D12=2050,SUMIFS(storage_capacity_2040,onshore_or_offshore,"Offshore storage",operational_category_high,2,offshore_region,C12))+IF(D12=2050,SUMIFS(storage_capacity_2050,onshore_or_offshore,"Offshore storage",operational_category_high,3,offshore_region,C12)) -> 1 | H12: Mtpa
A13: =VLOOKUP($C13,offshore_nodes!$A$2:$C$20,3,FALSE) -> 1 | B13: =VLOOKUP(C13,Table2[[OFF3]:[PECD]],2,FALSE) -> UK | C13: ASUK051 | D13: 2030 | E13: =SUMIFS(storage_capacity_2030,onshore_or_offshore,"Offshore storage",operational_category_low,1,offshore_region,C13)+IF(D13=2040,SUMIFS(storage_capacity_2040,onshore_or_offshore,"Offshore storage",operational_category_low,2,offshore_region,C13))+IF(D13=2050,SUMIFS(storage_capacity_2040,onshore_or_offshore,"Offshore storage",operational_category_low,2,offshore_region,C13))+IF(D13=2050,SUMIFS(storage_capacity_2050,onshore_or_offshore,"Offshore storage",operational_category_low,3,offshore_region,C13)) -> 0 | F13: =SUMIFS(storage_capacity_2030,onshore_or_offshore,"Offshore storage",operational_category_medium,1,offshore_region,C13)+IF(D13=2040,SUMIFS(storage_capacity_2040,onshore_or_offshore,"Offshore storage",operational_category_medium,2,offshore_region,C13))+IF(D13=2050,SUMIFS(storage_capacity_2040,onshore_or_offshore,"Offshore storage",operational_category_medium,2,offshore_region,C13))+IF(D13=2050,SUMIFS(storage_capacity_2050,onshore_or_offshore,"Offshore storage",operational_category_medium,3,offshore_region,C13)) -> 0 | G13: =SUMIFS(storage_capacity_2030,onshore_or_offshore,"Offshore storage",operational_category_high,1,offshore_region,C13)+IF(D13=2040,SUMIFS(storage_capacity_2040,onshore_or_offshore,"Offshore storage",operational_category_high,2,offshore_region,C13))+IF(D13=2050,SUMIFS(storage_capacity_2040,onshore_or_offshore,"Offshore storage",operational_category_high,2,offshore_region,C13))+IF(D13=2050,SUMIFS(storage_capacity_2050,onshore_or_offshore,"Offshore storage",operational_category_high,3,offshore_region,C13)) -> 0 | H13: Mtpa
... A58: =VLOOKUP($C58,offshore_nodes!$A$2:$C$20,3,FALSE) -> 8 | B58: =VLOOKUP(C58,Table2[[OFF3]:[PECD]],2,FALSE) -> UK | C58: NSUK052 | D58: 2050 | E58: =SUMIFS(storage_capacity_2030,onshore_or_offshore,"Offshore storage",operational_category_low,1,offshore_region,C58)+IF(D58=2040,SUMIFS(storage_capacity_2040,onshore_or_offshore,"Offshore storage",operational_category_low,2,offshore_region,C58))+IF(D58=2050,SUMIFS(storage_capacity_2040,onshore_or_offshore,"Offshore storage",operational_category_low,2,offshore_region,C58))+IF(D58=2050,SUMIFS(storage_capacity_2050,onshore_or_offshore,"Offshore storage",operational_category_low,3,offshore_region,C58)) -> 5 | F58: =SUMIFS(storage_capacity_2030,onshore_or_offshore,"Offshore storage",operational_category_medium,1,offshore_region,C58)+IF(D58=2040,SUMIFS(storage_capacity_2040,onshore_or_offshore,"Offshore storage",operational_category_medium,2,offshore_region,C58))+IF(D58=2050,SUMIFS(storage_capacity_2040,onshore_or_offshore,"Offshore storage",operational_category_medium,2,offshore_region,C58))+IF(D58=2050,SUMIFS(storage_capacity_2050,onshore_or_offshore,"Offshore storage",operational_category_medium,3,offshore_region,C58)) -> 20 | G58: =SUMIFS(storage_capacity_2030,onshore_or_offshore,"Offshore storage",operational_category_high,1,offshore_region,C58)+IF(D58=2040,SUMIFS(storage_capacity_2040,onshore_or_offshore,"Offshore storage",operational_category_high,2,offshore_region,C58))+IF(D58=2050,SUMIFS(storage_capacity_2040,onshore_or_offshore,"Offshore storage",operational_category_high,2,offshore_region,C58))+IF(D58=2050,SUMIFS(storage_capacity_2050,onshore_or_offshore,"Offshore storage",operational_category_high,3,offshore_region,C58)) -> 20 | H58: Mtpa

Sheet Storage_projects
A1: Category | B1: year of operation based on expert judgment
A2: 0 | B2: not operational
A3: 1 | B3: operational in 2030, 2040 and 2050
A4: 2 | B4: operational in 2040 and 2050
A5: 3 | B5: operational in 2050
L7: year of operation based on source
A8: low | B8: medium | C8: high | D8: OFF3 | E8: PECD | F8: Source | G8: Project | H8: Country | I8: Storage Basin / Reservoir | J8: xcoordinates | K8: ycoordinates | L8: 2025 | M8: 2026 | N8: 2027 | O8: 2028 | P8: 2029 | Q8: 2030 | R8: 2031 | S8: 2032 | T8: 2033 | U8: 2034 | V8: 2035 | W8: 2040 | X8: 2050 | Y8: Comment
A9: 1 | B9: =A9 -> 1 | C9: =B9 -> 1 | D9: NSNL031 | E9: NL | F9: JRC 2024 | G9: Porthos | H9: Netherlands | I9: Offshore storage | J9: 3.9377 | K9: 52.126 | N9: 2.5 | O9: 2.5 | P9: 2.5 | Q9: 2.5 | R9: 2.5 | S9: 2.5 | T9: 2.5 | U9: 2.5 | V9: 2.5 | W9: 2.5 | X9: =W9 -> 2.5 | Y9: JRC: Under development
A10: 1 | B10: =A10 -> 1 | C10: =B10 -> 1 | D10: NSDKW12 | E10: DK | F10: JRC 2024 | G10: Greensand | H10: Denmark | I10: Offshore storage | J10: 5.3 | K10: 56.43 | L10: 0 | M10: 1.5 | N10: 1.5 | O10: 1.5 | P10: 5 | Q10: 8 | R10: 8 | S10: 8 | T10: 8 | U10: 8 | V10: 8 | W10: 8 | X10: =W10 -> 8 | Y10: JRC: Pilot to commercial scale-up
A11: 1 | B11: =A11 -> 1 | C11: =B11 -> 1 | D11: NSDKW12 | E11: DK | F11: JRC 2024 | G11: Bifrost | H11: Denmark | I11: Offshore storage | J11: 4.5 | K11: 56.2 | L11: 0 | M11: 0 | N11: 0 | O11: 3 | P11: 3 | Q11: 3 | R11: 3 | S11: 3 | T11: 3 | U11: 3 | V11: 3 | W11: 3 | X11: =W11 -> 3 | Y11: JRC: Planned
A12: 1 | B12: =A12 -> 1 | C12: =B12 -> 1 | D12: ATUK031 | E12: UK | F12: JRC 2024 | G12: HyNet North West storage project | H12: United Kingdom | I12: Offshore storage | J12: -2.8433 | K12: 53.2769 | N12: 4.5 | O12: 4.5 | P12: 4.5 | Q12: 10 | R12: 10 | S12: 10 | T12: 10 | U12: 10 | V12: 10 | W12: 10 | X12: =W12 -> 10
A13: 1 | B13: =A13 -> 1 | C13: =B13 -> 1 | D13: ASNOS3 | E13: NO | F13: JRC 2024 | G13: Northern Lights | H13: Norway | I13: Offshore storage | J13: 3.6889006 | K13: 60.568692 | L13: 1.5 | M13: 1.5 | N13: 5.2 | O13: 5.2 | P13: 5.2 | Q13: 5.2 | R13: 5.2 | S13: 5.2 | T13: 5.2 | U13: 5.2 | V13: 5.2 | W13: 5.2 | X13: =W13 -> 5.2 | Y13: JRC: Under construction / operational ramp-up
A14: 1 | B14: =A14 -> 1 | C14: =B14 -> 1 | D14: NSNOS22 | E14: NO | F14: JRC 2024 | G14: Sleipner CO₂ Storage | H14: Norway | I14: Offshore storage | J14: 1.9 | K14: 58.37 | L14: 1 | M14: 1 | N14: 1 | O14: 1 | P14: 1 | Q14: 1 | R14: 1 | S14: 1 | T14: 1 | U14: 1 | V14: 1 | W14: 1 | X14: =W14 -> 1 | Y14: JRC: Operational
A15: 1 | B15: =A15 -> 1 | C15: =B15 -> 1 | D15: ASNON1 | E15: NO | F15: JRC 2024 | G15: Snøhvit CO₂ Storage | H15: Norway | I15: Offshore storage | J15: 22.1 | K15: 71.6 | L15: 0.7 | M15: 0.7 | N15: 0.7 | O15: 0.7 | P15: 0.7 | Q15: 0.7 | R15: 0.7 | S15: 0.7 | T15: 0.7 | U15: 0.7 | V15: 0.7 | W15: 0.7 | X15: =W15 -> 0.7 | Y15: JRC: Operational
A16: 1 | B16: =A16 -> 1 | C16: =B16 -> 1 | D16: EMGR02 | E16: GR | F16: JRC 2024 | G16: Prinos CO2 storage | H16: Greece | I16: Offshore storage | J16: 24.625 | K16: 40.967 | L16: 0 | M16: 0.1 | N16: 0.5 | O16: 2.5 | P16: 2.5 | Q16: 2.5 | R16: 2.5 | S16: 2.5 | T16: 2.5 | U16: 2.5 | V16: 2.5 | W16: 2.5 | X16: =W16 -> 2.5
A17: 1 | B17: =A17 -> 1 | C17: =B17 -> 1 | D17: WMITN1 | E17: IT | F17: JRC 2024 | G17: Ravenna storage | H17: Italy | I17: Offshore storage | J17: 12.2867 | K17: 44.4949 | O17: 4 | P17: 4 | Q17: 4 | R17: 4 | S17: 4 | T17: 4 | U17: 4 | V17: 4 | W17: 4 | X17: =W17 -> 4
A18: 2 | B18: 2 | C18: =B18 -> 2 | D18: NSNL012 | E18: NL | F18: JRC 2024 | G18: Aramis | H18: Netherlands | I18: Offshore storage | J18: 4.09 | K18: 53.72 | O18: 5 | P18: 5 | Q18: 5 | R18: 8 | S18: 8 | T18: 8 | U18: 8 | V18: 8 | W18: 8 | X18: =W18 -> 8 | Y18: JRC: Planned
A19: 2 | B19: 2 | C19: =B19 -> 2 | D19: ASNOS3 | E19: NO | F19: JRC 2024 | G19: Smeaheia | H19: Norway | I19: Offshore storage | J19: 4.077951 | K19: 60.652963 | O19: 20 | P19: 20 | Q19: 20 | R19: 20 | S19: 20 | T19: 20 | U19: 20 | V19: 20 | W19: 20 | X19: =W19 -> 20 | Y19: JRC: Planned
A20: 2 | B20: 1 | C20: 1 | D20: NSUK052 | E20: UK | F20: JRC 2024 | G20: Acorn CCS | H20: United Kingdom | I20: Offshore storage | J20: 1.3 | K20: 57.9 | N20: 1 | O20: 1 | P20: 1 | Q20: 5 | R20: 5 | S20: 5 | T20: 5 | U20: 5 | V20: 5 | W20: 5 | X20: =W20 -> 5 | Y20: JRC: Advanced development. CATF: mentions up to 20 Mt/annum
A21: 2 | B21: 1 | C21: 1 | D21: NSUK042 | E21: UK | F21: JRC 2024 | G21: Viking CCS | H21: United Kingdom | I21: Offshore storage | J21: 2 | K21: 53.5 | N21: 3.6 | O21: 3.6 | P21: 3.6 | Q21: 10 | R21: 10 | S21: 10 | T21: 10 | U21: 10 | V21: 10 | W21: 10 | X21: =W21 -> 10 | Y21: JRC: Advanced development
A22: 2 | B22: 2 | C22: 2 | D22: NSUK011 | E22: UK | F22: JRC 2024 | G22: Bacton Thames Net Zero Initiative | H22: United Kingdom | I22: Offshore storage | J22: 1.478 | K22: 52.853 | N22: 10 | O22: 10 | P22: 10 | Q22: 10 | R22: 10 | S22: 10 | T22: 10 | U22: 10 | V22: 10 | W22: 10 | X22: =W22 -> 10 | Y22: CATF: Mentions up to 20 Mt/annum
A23: 3 | B23: 2 | C23: 2 | D23: NSUK012 | E23: UK | F23: JRC 2024 | G23: Poseidon (UK) | H23: United Kingdom | I23: Offshore storage | J23: 2.17 | K23: 53.08 | R23: 1.5 | S23: 1.5 | T23: 1.5 | U23: 1.5 | V23: 1.5 | W23: 1.5 | X23: =W23 -> 1.5 | Y23: CATF: in development
A24: 2 | B24: 2 | C24: 2 | D24: NSUK042 | E24: UK | F24: JRC 2024 | G24: Northen Endurance Partnership | H24: United Kingdom | I24: Offshore storage | J24: 1 | K24: 54.5 | M24: 5 | N24: 5 | O24: 5 | P24: 15 | Q24: 15 | R24: 15 | S24: 15 | T24: 15 | U24: 15 | V24: 15 | W24: 15 | X24: =W24 -> 15 | Y24: CATF: in development
A25: 3 | B25: 2 | C25: 2 | D25: NSUK041 | E25: UK | F25: JRC 2024 | G25: Orion | H25: United Kingdom | I25: Offshore storage | J25: 0.4 | K25: 53.9 | S25: 1 | T25: 1 | U25: 1 | V25: 1 | W25: 1 | X25: =W25 -> 1
A26: 2 | B26: 2 | C26: 2 | D26: NSNOS22 | E26: NO | F26: JRC 2024 | G26: Poseidon CCS | H26: Norway | I26: Offshore storage | J26: 4.963814 | K26: 57.716041 | Q26: 5 | R26: 5 | S26: 5 | T26: 5 | U26: 5 | V26: 5 | W26: 5 | X26: =W26 -> 5 | Y26: JRC: Pilot/planned
A27: 2 | B27: 2 | C27: 2 | D27: ASNOS3 | E27: NO | F27: JRC 2024 | G27: Luna CCS | H27: Norway | I27: Offshore storage | J27: 3.2 | K27: 61 | P27: 5 | Q27: 5 | R27: 5 | S27: 5 | T27: 5 | U27: 5 | V27: 5 | W27: 5 | X27: =W27 -> 5 | Y27: JRC: Emerging
A28: 2 | B28: 2 | C28: 2 | D28: ASNON1 | E28: NO | F28: JRC 2024 | G28: Polaris / Barents Blue | H28: Norway | I28: Offshore storage | J28: 24.3 | K28: 71.2 | Q28: 3 | R28: 3 | S28: 3 | T28: 3 | U28: 3 | V28: 3 | W28: 3 | X28: =W28 -> 3 | Y28: JRC: Planned
A29: 3 | B29: 2 | C29: 2 | D29: NSNOS22 | E29: NO | F29: JRC 2024 | G29: Trudvang CCS | H29: Norway | I29: Offshore storage | J29: 1.9 | K29: 58.2 | Q29: 9 | R29: 9 | S29: 9 | T29: 9 | U29: 9 | V29: 9 | W29: 9 | X29: =W29 -> 9 | Y29: JRC: Exploration
A30: 3 | B30: 2 | C30: 2 | D30: ASNOS3 | E30: NO | F30: JRC 2024 | G30: Havstjerne | H30: Norway | I30: Offshore storage | J30: 2.8 | K30: 59.7 | N30: 7 | O30: 7 | P30: 7 | Q30: 7 | R30: 7 | S30: 7 | T30: 7 | U30: 7 | V30: 7 | W30: 7 | X30: =W30 -> 7 | Y30: JRC: Early-stage
A31: 3 | B31: 3 | C31: 2 | D31: ATIE03 | E31: IE | F31: JRC 2024 | G31: Ervia Cork CCS | H31: Ireland | I31: Offshore storage | J31: -8.251 | K31: 51.8 | O31: 2.5 | P31: 2.5 | Q31: 2.5 | R31: 2.5 | S31: 2.5 | T31: 2.5 | U31: 2.5 | V31: 2.5 | W31: 2.5 | X31: =W31 -> 2.5
A32: 0 | B32: 3 | C32: 2 | D32: - | E32: DK | F32: JRC 2024 | G32: Stenlille demo project | H32: Denmark | I32: Onshore storage | J32: - | K32: - | L32: 0.5 | M32: 0.5 | N32: 0.5 | O32: 0.5 | P32: 0.5 | Q32: 0.5 | R32: 0.5 | S32: 0.5 | T32: 0.5 | U32: 0.5 | V32: 0.5 | W32: 0.5 | X32: =W32 -> 0.5
A33: 0 | B33: 3 | C33: 2 | D33: - | E33: DK | F33: JRC 2024 | G33: Trelleborg (Norne) | H33: Denmark | I33: Onshore storage | J33: - | K33: - | N33: 1.15 | O33: 1.15 | P33: 1.15 | Q33: 10 | R33: 10 | S33: 10 | T33: 10 | U33: 10 | V33: 10 | W33: 10 | X33: =W33 -> 10
A34: 0 | B34: 3 | C34: 2 | D34: - | E34: DK | F34: JRC 2024 | G34: Fyrkat (Norne) | H34: Denmark | I34: Onshore storage | J34: - | K34: - | N34: 1.15 | O34: 1.15 | P34: 1.15 | Q34: 8 | R34: 8 | S34: 8 | T34: 8 | U34: 8 | V34: 8 | W34: 8 | X34: =W34 -> 8
A35: 0 | B35: 3 | C35: 2 | D35: - | E35: DK | F35: JRC 2024 | G35: Ruby storage project | H35: Denmark | I35: Onshore storage | J35: - | K35: - | N35: 1 | O35: 1 | P35: 1 | Q35: 7 | R35: 7 | S35: 7 | T35: 7 | U35: 7 | V35: 7 | W35: 7 | X35: =W35 -> 7
A36: 0 | B36: 3 | C36: 2 | D36: - | E36: FR | F36: JRC 2024 | G36: Lacq storage site | H36: France | I36: Onshore storage | J36: - | K36: - | R36: 2.5 | S36: 2.5 | T36: 2.5 | U36: 2.5 | V36: 2.5 | W36: 2.5 | X36: =W36 -> 2.5
A37: 0 | B37: 3 | C37: 2 | D37: - | E37: BG | F37: CATF, 2023 | G37: Devnya storage site | H37: Bulgaria | I37: Onshore storage | J37: - | K37: - | O37: 1.5 | P37: 1.5 | Q37: 1.5 | R37: 1.5 | S37: 1.5 | T37: 1.5 | U37: 1.5 | V37: 1.5 | W37: 1.5 | X37: =W37 -> 1.5
A38: 0 | B38: 3 | C38: 2 | D38: - | E38: HR | F38: CATF, 2023 | G38: Bockovac | H38: Croatia | I38: Onshore storage | J38: - | K38: - | O38: 1.5 | P38: 1.5 | Q38: 1.5 | R38: 1.5 | S38: 1.5 | T38: 1.5 | U38: 1.5 | V38: 1.5 | W38: 1.5 | X38: =W38 -> 1.5
A39: 0 | B39: 3 | C39: 2 | D39: - | E39: RO | F39: CATF, 2023 | G39: Fieni-Botești | H39: Romania | I39: Onshore storage | J39: - | K39: - | P39: 0.6 | Q39: 0.6 | R39: 0.6 | S39: 0.6 | T39: 0.6 | U39: 0.6 | V39: 0.6 | W39: 0.6 | X39: =W39 -> 0.6
A40: 0 | B40: 3 | C40: 2 | D40: WMES06 | E40: ES | F40: CATF, 2023 | G40: Tarraco2 | H40: Spain | I40: Offshore storage | J40: 1.27 | K40: 40.6 | W40: 2 | X40: =W40 -> 2 | Y40: 2040 assumed
A41: 0 | B41: 2 | C41: 2 | D41: NSNL012 | E41: NL | F41: CATF, 2023 | G41: L10 | H41: Netherlands | I41: Offshore storage | J41: 4.201944 | K41: 53.403889 | W41: 5 | X41: =W41 -> 5 | Y41: 2040 assumed
...

Sheet Totals
B1: Mtpa | E1: % of total scenario potential
B2: low | C2: medium | D2: high | E2: Low | F2: Medium | G2: High
A3: 2030 | B3: =SUMIF(Storage_projects!A$9:A$55,1,Storage_projects!$Q$9:$Q$55) -> 36.9 | C3: =SUMIF(Storage_projects!B$9:B$55,1,Storage_projects!$Q$9:$Q$55) -> 51.9 | D3: =SUMIF(Storage_projects!C$9:C$55,1,Storage_projects!$Q$9:$Q$55) -> 51.9 | E3: =B3/B$5 -> 0.26565875 | F3: =C3/C$5 -> 0.18976234 | G3: =D3/D$5 -> 0.13895582
A4: 2040 | B4: =SUMIF(Storage_projects!A$9:A$55,1,Storage_projects!$W$9:$W$55)+SUMIF(Storage_projects!A$9:A$55,2,Storage_projects!$W$9:$W$55) -> 117.9 | C4: =SUMIF(Storage_projects!B$9:B$55,1,Storage_projects!$W$9:$W$55)+SUMIF(Storage_projects!B$9:B$55,2,Storage_projects!$W$9:$W$55) -> 202.9 | D4: =SUMIF(Storage_projects!C$9:C$55,1,Storage_projects!$W$9:$W$55)+SUMIF(Storage_projects!C$9:C$55,2,Storage_projects!$W$9:$W$55) -> 313.5 | E4: =B4/B$5 -> 0.8488121 | F4: =C4/C$5 -> 0.74186472 | G4: =D4/D$5 -> 0.83935743
A5: 2050 | B5: =SUMIF(Storage_projects!A$9:A$55,1,Storage_projects!$X$9:$X$55)+SUMIF(Storage_projects!A$9:A$55,2,Storage_projects!$X$9:$X$55)+SUMIF(Storage_projects!A$9:A$55,3,Storage_projects!$X$9:$X$55) -> 138.9 | C5: =SUMIF(Storage_projects!B$9:B$55,1,Storage_projects!$X$9:$X$55)+SUMIF(Storage_projects!B$9:B$55,2,Storage_projects!$X$9:$X$55)+SUMIF(Storage_projects!B$9:B$55,3,Storage_projects!$X$9:$X$55) -> 273.5 | D5: =SUMIF(Storage_projects!C$9:C$55,1,Storage_projects!$X$9:$X$55)+SUMIF(Storage_projects!C$9:C$55,2,Storage_projects!$X$9:$X$55)+SUMIF(Storage_projects!C$9:C$55,3,Storage_projects!$X$9:$X$55) -> 373.5 | E5: =B5/B$5 -> 1 | F5: =C5/C$5 -> 1 | G5: =D5/D$5 -> 1
A7: check totals | B7: low | C7: medium | D7: high
A8: 2030 | B8: =SUMIF(Onshore_storage_potentials!$B$2:$B$16,Totals!$A8,Onshore_storage_potentials!C$2:C$16)+SUMIF(Offshore_storage_potentials!$D$2:$D$58,Totals!$A8,Offshore_storage_potentials!E$2:E$58) -> 36.9 | C8: =SUMIF(Onshore_storage_potentials!$B$2:$B$16,Totals!$A8,Onshore_storage_potentials!D$2:D$16)+SUMIF(Offshore_storage_potentials!$D$2:$D$58,Totals!$A8,Offshore_storage_potentials!F$2:F$58) -> 51.9 | D8: =SUMIF(Onshore_storage_potentials!$B$2:$B$16,Totals!$A8,Onshore_storage_potentials!E$2:E$16)+SUMIF(Offshore_storage_potentials!$D$2:$D$58,Totals!$A8,Offshore_storage_potentials!G$2:G$58) -> 51.9 | E8: =B8-B3 -> 0 | F8: =C8-C3 -> 0 | G8: =D8-D3 -> 0
A9: 2040 | B9: =SUMIF(Onshore_storage_potentials!$B$2:$B$16,Totals!$A9,Onshore_storage_potentials!C$2:C$16)+SUMIF(Offshore_storage_potentials!$D$2:$D$58,Totals!$A9,Offshore_storage_potentials!E$2:E$58) -> 117.9 | C9: =SUMIF(Onshore_storage_potentials!$B$2:$B$16,Totals!$A9,Onshore_storage_potentials!D$2:D$16)+SUMIF(Offshore_storage_potentials!$D$2:$D$58,Totals!$A9,Offshore_storage_potentials!F$2:F$58) -> 202.9 | D9: =SUMIF(Onshore_storage_potentials!$B$2:$B$16,Totals!$A9,Onshore_storage_potentials!E$2:E$16)+SUMIF(Offshore_storage_potentials!$D$2:$D$58,Totals!$A9,Offshore_storage_potentials!G$2:G$58) -> 313.5 | E9: =B9-B4 -> 0 | F9: =C9-C4 -> 0 | G9: =D9-D4 -> 0
A10: 2050 | B10: =SUMIF(Onshore_storage_potentials!$B$2:$B$16,Totals!$A10,Onshore_storage_potentials!C$2:C$16)+SUMIF(Offshore_storage_potentials!$D$2:$D$58,Totals!$A10,Offshore_storage_potentials!E$2:E$58) -> 138.9 | C10: =SUMIF(Onshore_storage_potentials!$B$2:$B$16,Totals!$A10,Onshore_storage_potentials!D$2:D$16)+SUMIF(Offshore_storage_potentials!$D$2:$D$58,Totals!$A10,Offshore_storage_potentials!F$2:F$58) -> 273.5 | D10: =SUMIF(Onshore_storage_potentials!$B$2:$B$16,Totals!$A10,Onshore_storage_potentials!E$2:E$16)+SUMIF(Offshore_storage_potentials!$D$2:$D$58,Totals!$A10,Offshore_storage_potentials!G$2:G$58) -> 373.5 | E10: =B10-B5 -> 0 | F10: =C10-C5 -> 0 | G10: =D10-D5 -> 0

Sheet offshore_nodes
A1: OFF3 | B1: Country | C1: #region
A2: NSDE011 | B2: DE | C2: 1
A3: NSDKW12 | B3: DK | C3: 1
A4: WMES06 | B4: ES | C4: 1
A5: EMGR02 | B5: GR | C5: 1
A6: ATIE03 | B6: IE | C6: 1
A7: WMITN1 | B7: IT | C7: 1
A8: NSNL012 | B8: NL | C8: 1
A9: NSNL031 | B9: NL | C9: 2
A10: ASNON1 | B10: NO | C10: 1
A11: ASNOS3 | B11: NO | C11: 2
A12: NSNOS22 | B12: NO | C12: 3
A13: ASUK051 | B13: UK | C13: 1
... A20: NSUK052 | B20: UK | C20: 8
