Workbook
Name CO2_harbor_hubs: X_Y_CO2_harbor_hubs!$B$2:$B$100
Name exchange_rate_USD25_EUR25: Info!$E$34
Name per_ton_offshore_storage_costs: Info!$E$29
Name per_ton_onshore_storage_costs: Info!$E$28
Name pipe_a: Info!$E$30
Name pipe_b: Info!$E$31
Name ship_a: Info!$E$32
Name ship_b: Info!$E$33
Name Threshold: Info!$E$27

Sheet Info
A1: Date | B1: 46272.416
A2: Project | B2: Mopo
A3: Name | B3: Marit van Hout
A4: Organisation | B4: PBL
A5: Content | B5: This document contains data on the CO2 network layout, transport mode (pipeline or shipping), and the accompanying costs derived from Barlow et al. (2025) and Hatta et al. (2025). Where we simplify assumptions assuming a threshold value indicating which transport mode is most economical. This then determines the costs for the particular link. The costs represent a 'processing_fee', representing (annualized) total costs of required network investments and operational costs. Four types of nodes are considered in the network: onshore storage nodes, offshore storage nodes, CO2 harbor hubs and regional/country nodes where the CO2 is gathered from capture units (or passing through). The distances between nodes are derived using QGIS (Open source GIS program). The main output of this file used for the modelling in SpineOpt is CO2_network_links_and_costs, with "_panEU" input to Pan EU study, and with "_IC1" input to the industrial case study for NL/BE. The links are two-directional.
A17: Link types: | B17: Assumptions
A18: Link_region_hub_to_onshore_storage | B18: Each onshore storage facility is assumed to only be directly connected to the corresponding regional hub, hence only onshore storage costs apply, transportation costs are zero. The location of the regional hubs is determined by their centroid location.
A19: Link_region_hub_to_offshore_storage | B19: Each offshore storage facility is assumed to be connected to a single regional hub only (e.g. "NO" to "offsh_CO2_storage_ASNON1"). N.B. per OFF3 region a single location (x/y) is determined, derived by calculating the weight average location based on (potential) capacity of the CCS projects located in the corresponding OFF3 region. If there is only 1 project per OFF3 region, the location of the offshore storage node represents the location of the specific project. Transportation costs (distance determines transport mode) and offshore storage costs determine the costs per ton of CO2.
A20: Link_region_hub_to_region_hub(via harbors) | B20: We assume that some regional hubs can be connected to other regional hubs via harbors if the latter is directly connected to an offshore storage facility. With the exeption of northwest NO that can only be connected through "NO". Transportation costs (distance determines transport mode) determine the costs per ton of CO2.
A21: Link_region_hub_to_region_hub | B21: Regional hubs can only be connected to regional hubs of neighboring regions/countries
A26: Assumptions
A27: Intersection = threshold | E27: 863.7 | F27: km
A28: Storage costs | D28: onshore | E28: =storage_costs!B2*exchange_rate_USD25_EUR25 -> 7.5327 | F28: €2025/ton CO2
D29: offshore | E29: =storage_costs!B3*exchange_rate_USD25_EUR25 -> 15.9516 | F29: €2025/ton CO2
A30: Pipeline costs in euro25/km/ton | D30: a | E30: =pipeline_costs!C5 -> 0.04431
D31: b | E31: 0
A32: Shipping costs in euro25/km/ton | D32: a | E32: =shipping_costs!C19 -> 0.0124
D33: b | E33: =shipping_costs!C20 -> 27.552
A34: Exchange rate USD2025/Euro2025 | E34: 0.8862
A35: EUR2009_TO_EUR2025 (HICP Eurostat) | E35: =135.86/91.2 -> 1.489693

Sheet CO2_netw_links_and_costs_panEU
A1: CO2_network_component | B1: Commodity | C1: NodeA | D1: NodeB | E1: transport_mode | F1: distance_km | G1: CO2_processing_tariff_euro/ton
A2: A.Link_region_hub_to_onshore_storage | B2: CO2 | C2: DK | D2: DK | E2: =IF(F2<>"",(IF(F2<Info!$E$27,"pipeline","shipping")),"-") -> - | G2: =per_ton_onshore_storage_costs -> 7.5327
A3: A.Link_region_hub_to_onshore_storage | B3: CO2 | C3: FR | D3: FR | E3: =IF(F3<>"",(IF(F3<Info!$E$27,"pipeline","shipping")),"-") -> - | G3: =per_ton_onshore_storage_costs -> 7.5327
A4: A.Link_region_hub_to_onshore_storage | B4: CO2 | C4: RO | D4: RO | E4: =IF(F4<>"",(IF(F4<Info!$E$27,"pipeline","shipping")),"-") -> - | G4: =per_ton_onshore_storage_costs -> 7.5327
A5: A.Link_region_hub_to_onshore_storage | B5: CO2 | C5: HR | D5: HR | E5: =IF(F5<>"",(IF(F5<Info!$E$27,"pipeline","shipping")),"-") -> - | G5: =per_ton_onshore_storage_costs -> 7.5327
A6: A.Link_region_hub_to_onshore_storage | B6: CO2 | C6: BG | D6: BG | E6: =IF(F6<>"",(IF(F6<Info!$E$27,"pipeline","shipping")),"-") -> - | G6: =per_ton_onshore_storage_costs -> 7.5327
A7: B.Link_region_hub_to_offshore_storage | B7: CO2 | C7: UK | D7: ATUK043 | E7: =IF(F7<>"",(IF(F7<Info!$E$27,"pipeline","shipping")),"-") -> pipeline | F7: 23.069447 | G7: =IF(E7="pipeline",F7*pipe_a+pipe_b,F7*ship_a+ship_b)+per_ton_offshore_storage_costs -> 16.973807
A8: B.Link_region_hub_to_offshore_storage | B8: CO2 | C8: UK | D8: ATUK031 | E8: =IF(F8<>"",(IF(F8<Info!$E$27,"pipeline","shipping")),"-") -> pipeline | F8: 97.658921 | G8: =IF(E8="pipeline",F8*pipe_a+pipe_b,F8*ship_a+ship_b)+per_ton_offshore_storage_costs -> 20.278867
A9: B.Link_region_hub_to_offshore_storage | B9: CO2 | C9: NL | D9: NSNL031 | E9: =IF(F9<>"",(IF(F9<Info!$E$27,"pipeline","shipping")),"-") -> pipeline | F9: 108.35417 | G9: =IF(E9="pipeline",F9*pipe_a+pipe_b,F9*ship_a+ship_b)+per_ton_offshore_storage_costs -> 20.752773
A10: B.Link_region_hub_to_offshore_storage | B10: CO2 | C10: IE | D10: ATIE03 | E10: =IF(F10<>"",(IF(F10<Info!$E$27,"pipeline","shipping")),"-") -> pipeline | F10: 153.52377 | G10: =IF(E10="pipeline",F10*pipe_a+pipe_b,F10*ship_a+ship_b)+per_ton_offshore_storage_costs -> 22.754238
A11: B.Link_region_hub_to_offshore_storage | B11: CO2 | C11: NL | D11: NSNL012 | E11: =IF(F11<>"",(IF(F11<Info!$E$27,"pipeline","shipping")),"-") -> pipeline | F11: 182.35027 | G11: =IF(E11="pipeline",F11*pipe_a+pipe_b,F11*ship_a+ship_b)+per_ton_offshore_storage_costs -> 24.031541
A12: B.Link_region_hub_to_offshore_storage | B12: CO2 | C12: IT | D12: WMITN1 | E12: =IF(F12<>"",(IF(F12<Info!$E$27,"pipeline","shipping")),"-") -> pipeline | F12: 189.67914 | G12: =IF(E12="pipeline",F12*pipe_a+pipe_b,F12*ship_a+ship_b)+per_ton_offshore_storage_costs -> 24.356282
A13: B.Link_region_hub_to_offshore_storage | B13: CO2 | C13: UK | D13: NSUK041 | E13: =IF(F13<>"",(IF(F13<Info!$E$27,"pipeline","shipping")),"-") -> pipeline | F13: 217.74409 | G13: =IF(E13="pipeline",F13*pipe_a+pipe_b,F13*ship_a+ship_b)+per_ton_offshore_storage_costs -> 25.599841
A14: B.Link_region_hub_to_offshore_storage | B14: CO2 | C14: GR | D14: EMGR02 | E14: =IF(F14<>"",(IF(F14<Info!$E$27,"pipeline","shipping")),"-") -> pipeline | F14: 255.00563 | G14: =IF(E14="pipeline",F14*pipe_a+pipe_b,F14*ship_a+ship_b)+per_ton_offshore_storage_costs -> 27.250899
A15: B.Link_region_hub_to_offshore_storage | B15: CO2 | C15: UK | D15: NSUK042 | E15: =IF(F15<>"",(IF(F15<Info!$E$27,"pipeline","shipping")),"-") -> pipeline | F15: 274.12032 | G15: =IF(E15="pipeline",F15*pipe_a+pipe_b,F15*ship_a+ship_b)+per_ton_offshore_storage_costs -> 28.097871
A16: B.Link_region_hub_to_offshore_storage | B16: CO2 | C16: DK | D16: NSDKW12 | E16: =IF(F16<>"",(IF(F16<Info!$E$27,"pipeline","shipping")),"-") -> pipeline | F16: 307.90075 | G16: =IF(E16="pipeline",F16*pipe_a+pipe_b,F16*ship_a+ship_b)+per_ton_offshore_storage_costs -> 29.594682
A17: B.Link_region_hub_to_offshore_storage | B17: CO2 | C17: UK | D17: NSUK011 | E17: =IF(F17<>"",(IF(F17<Info!$E$27,"pipeline","shipping")),"-") -> pipeline | F17: 324.19534 | G17: =IF(E17="pipeline",F17*pipe_a+pipe_b,F17*ship_a+ship_b)+per_ton_offshore_storage_costs -> 30.316695
A18: B.Link_region_hub_to_offshore_storage | B18: CO2 | C18: UK | D18: NSUK012 | E18: =IF(F18<>"",(IF(F18<Info!$E$27,"pipeline","shipping")),"-") -> pipeline | F18: 355.74986 | G18: =IF(E18="pipeline",F18*pipe_a+pipe_b,F18*ship_a+ship_b)+per_ton_offshore_storage_costs -> 31.714876
... A25: B.Link_region_hub_to_offshore_storage | B25: CO2 | C25: NO | D25: NSNOS22 | E25: =IF(F25<>"",(IF(F25<Info!$E$27,"pipeline","shipping")),"-") -> shipping | F25: 929.19838 | G25: =IF(E25="pipeline",F25*pipe_a+pipe_b,F25*ship_a+ship_b)+per_ton_offshore_storage_costs -> 55.02566
A26: C.Link_region_hub_to_region_hub(via harbors) | B26: CO2 | C26: UK | D26: NL | E26: =IF(F26<>"",(IF(F26<Info!$E$27,"pipeline","shipping")),"-") -> pipeline | F26: 465 | G26: =IF(E26="pipeline",F26*pipe_a+pipe_b,F26*ship_a+ship_b) -> 20.60415
A27: C.Link_region_hub_to_region_hub(via harbors) | B27: CO2 | C27: NL | D27: DK | E27: =IF(F27<>"",(IF(F27<Info!$E$27,"pipeline","shipping")),"-") -> pipeline | F27: 521 | G27: =IF(E27="pipeline",F27*pipe_a+pipe_b,F27*ship_a+ship_b) -> 23.08551
A28: C.Link_region_hub_to_region_hub(via harbors) | B28: CO2 | C28: BE | D28: UK | E28: =IF(F28<>"",(IF(F28<Info!$E$27,"pipeline","shipping")),"-") -> pipeline | F28: 568 | G28: =IF(E28="pipeline",F28*pipe_a+pipe_b,F28*ship_a+ship_b) -> 25.16808
A29: C.Link_region_hub_to_region_hub(via harbors) | B29: CO2 | C29: BE | D29: DK | E29: =IF(F29<>"",(IF(F29<Info!$E$27,"pipeline","shipping")),"-") -> pipeline | F29: 622 | G29: =IF(E29="pipeline",F29*pipe_a+pipe_b,F29*ship_a+ship_b) -> 27.56082
A30: C.Link_region_hub_to_region_hub(via harbors) | B30: CO2 | C30: UK | D30: DK | E30: =IF(F30<>"",(IF(F30<Info!$E$27,"pipeline","shipping")),"-") -> pipeline | F30: 627 | G30: =IF(E30="pipeline",F30*pipe_a+pipe_b,F30*ship_a+ship_b) -> 27.78237
A31: C.Link_region_hub_to_region_hub(via harbors) | B31: CO2 | C31: NO | D31: DK | E31: =IF(F31<>"",(IF(F31<Info!$E$27,"pipeline","shipping")),"-") -> pipeline | F31: 636 | G31: =IF(E31="pipeline",F31*pipe_a+pipe_b,F31*ship_a+ship_b) -> 28.18116
A32: C.Link_region_hub_to_region_hub(via harbors) | B32: CO2 | C32: UK | D32: DE | E32: =IF(F32<>"",(IF(F32<Info!$E$27,"pipeline","shipping")),"-") -> pipeline | F32: 746 | G32: =IF(E32="pipeline",F32*pipe_a+pipe_b,F32*ship_a+ship_b) -> 33.05526
A33: C.Link_region_hub_to_region_hub(via harbors) | B33: CO2 | C33: UK | D33: NO | E33: =IF(F33<>"",(IF(F33<Info!$E$27,"pipeline","shipping")),"-") -> pipeline | F33: 752 | G33: =IF(E33="pipeline",F33*pipe_a+pipe_b,F33*ship_a+ship_b) -> 33.32112
A34: C.Link_region_hub_to_region_hub(via harbors) | B34: CO2 | C34: DE | D34: NO | E34: =IF(F34<>"",(IF(F34<Info!$E$27,"pipeline","shipping")),"-") -> shipping | F34: 883 | G34: =IF(E34="pipeline",F34*pipe_a+pipe_b,F34*ship_a+ship_b) -> 38.5012
A35: C.Link_region_hub_to_region_hub(via harbors) | B35: CO2 | C35: NL | D35: NO | E35: =IF(F35<>"",(IF(F35<Info!$E$27,"pipeline","shipping")),"-") -> shipping | F35: 985 | G35: =IF(E35="pipeline",F35*pipe_a+pipe_b,F35*ship_a+ship_b) -> 39.766
A36: C.Link_region_hub_to_region_hub(via harbors) | B36: CO2 | C36: BE | D36: NO | E36: =IF(F36<>"",(IF(F36<Info!$E$27,"pipeline","shipping")),"-") -> shipping | F36: 1039 | G36: =IF(E36="pipeline",F36*pipe_a+pipe_b,F36*ship_a+ship_b) -> 40.4356
A37: C.Link_region_hub_to_region_hub(via harbors) | B37: CO2 | C37: NL | D37: IE | E37: =IF(F37<>"",(IF(F37<Info!$E$27,"pipeline","shipping")),"-") -> shipping | F37: 1192 | G37: =IF(E37="pipeline",F37*pipe_a+pipe_b,F37*ship_a+ship_b) -> 42.3328
... A146: D.Link_region_hub_to_region_hub | B146: CO2 | C146: MT | D146: ES | E146: =IF(F146<>"",(IF(F146<Info!$E$27,"pipeline","shipping")),"-") -> shipping | F146: 1641 | G146: =IF(E146="pipeline",F146*pipe_a+pipe_b,F146*ship_a+ship_b) -> 47.9004

Sheet CO2_netw_links_and_costs_IC1
A1: CO2_network_component | B1: Commodity | C1: NodeA | D1: NodeB | E1: transport_mode | F1: distance_km | G1: CO2_processing_tariff_euro/ton
A2: A.Link_region_hub_to_onshore_storage | B2: CO2 | C2: DK | D2: DK | E2: =IF(F2<>"",(IF(F2<Info!$E$27,"pipeline","shipping")),"-") -> - | G2: =per_ton_onshore_storage_costs -> 7.5327
A3: A.Link_region_hub_to_onshore_storage | B3: CO2 | C3: FR | D3: FR | E3: =IF(F3<>"",(IF(F3<Info!$E$27,"pipeline","shipping")),"-") -> - | G3: =per_ton_onshore_storage_costs -> 7.5327
A4: A.Link_region_hub_to_onshore_storage | B4: CO2 | C4: RO | D4: RO | E4: =IF(F4<>"",(IF(F4<Info!$E$27,"pipeline","shipping")),"-") -> - | G4: =per_ton_onshore_storage_costs -> 7.5327
A5: A.Link_region_hub_to_onshore_storage | B5: CO2 | C5: HR | D5: HR | E5: =IF(F5<>"",(IF(F5<Info!$E$27,"pipeline","shipping")),"-") -> - | G5: =per_ton_onshore_storage_costs -> 7.5327
A6: A.Link_region_hub_to_onshore_storage | B6: CO2 | C6: BG | D6: BG | E6: =IF(F6<>"",(IF(F6<Info!$E$27,"pipeline","shipping")),"-") -> - | G6: =per_ton_onshore_storage_costs -> 7.5327
A7: B.Link_region_hub_to_offshore_storage | B7: CO2 | C7: UK | D7: ATUK043 | E7: =IF(F7<>"",(IF(F7<Info!$E$27,"pipeline","shipping")),"-") -> pipeline | F7: 23.069447 | G7: =IF(E7="pipeline",CO2_netw_links_and_costs_IC1!F7*pipe_a+pipe_b,CO2_netw_links_and_costs_IC1!F7*ship_a+ship_b)+per_ton_offshore_storage_costs -> 16.973807
A8: B.Link_region_hub_to_offshore_storage | B8: CO2 | C8: UK | D8: ATUK031 | E8: =IF(F8<>"",(IF(F8<Info!$E$27,"pipeline","shipping")),"-") -> pipeline | F8: 97.658921 | G8: =IF(E8="pipeline",CO2_netw_links_and_costs_IC1!F8*pipe_a+pipe_b,CO2_netw_links_and_costs_IC1!F8*ship_a+ship_b)+per_ton_offshore_storage_costs -> 20.278867
A9: B.Link_region_hub_to_offshore_storage | B9: CO2 | C9: NLC1 | D9: NSNL012 | E9: =IF(F9<>"",(IF(F9<Info!$E$27,"pipeline","shipping")),"-") -> pipeline | F9: 179 | G9: =IF(E9="pipeline",CO2_netw_links_and_costs_IC1!F9*pipe_a+pipe_b,CO2_netw_links_and_costs_IC1!F9*ship_a+ship_b)+per_ton_offshore_storage_costs -> 23.88309
A10: B.Link_region_hub_to_offshore_storage | B10: CO2 | C10: NLC5 | D10: NSNL012 | E10: =IF(F10<>"",(IF(F10<Info!$E$27,"pipeline","shipping")),"-") -> pipeline | F10: 181.22625 | G10: =IF(E10="pipeline",CO2_netw_links_and_costs_IC1!F10*pipe_a+pipe_b,CO2_netw_links_and_costs_IC1!F10*ship_a+ship_b)+per_ton_offshore_storage_costs -> 23.981735
A11: B.Link_region_hub_to_offshore_storage | B11: CO2 | C11: NLC6 | D11: NSNL012 | E11: =IF(F11<>"",(IF(F11<Info!$E$27,"pipeline","shipping")),"-") -> pipeline | F11: 215.59481 | G11: =IF(E11="pipeline",CO2_netw_links_and_costs_IC1!F11*pipe_a+pipe_b,CO2_netw_links_and_costs_IC1!F11*ship_a+ship_b)+per_ton_offshore_storage_costs -> 25.504606
A12: B.Link_region_hub_to_offshore_storage | B12: CO2 | C12: IE | D12: ATIE03 | E12: =IF(F12<>"",(IF(F12<Info!$E$27,"pipeline","shipping")),"-") -> pipeline | F12: 153.52377 | G12: =IF(E12="pipeline",CO2_netw_links_and_costs_IC1!F12*pipe_a+pipe_b,CO2_netw_links_and_costs_IC1!F12*ship_a+ship_b)+per_ton_offshore_storage_costs -> 22.754238
A13: B.Link_region_hub_to_offshore_storage | B13: CO2 | C13: NLC1 | D13: NSNL031 | E13: =IF(F13<>"",(IF(F13<Info!$E$27,"pipeline","shipping")),"-") -> pipeline | F13: 272 | G13: =IF(E13="pipeline",CO2_netw_links_and_costs_IC1!F13*pipe_a+pipe_b,CO2_netw_links_and_costs_IC1!F13*ship_a+ship_b)+per_ton_offshore_storage_costs -> 28.00392
A14: B.Link_region_hub_to_offshore_storage | B14: CO2 | C14: NLC5 | D14: NSNL031 | E14: =IF(F14<>"",(IF(F14<Info!$E$27,"pipeline","shipping")),"-") -> pipeline | F14: 70.80427 | G14: =IF(E14="pipeline",CO2_netw_links_and_costs_IC1!F14*pipe_a+pipe_b,CO2_netw_links_and_costs_IC1!F14*ship_a+ship_b)+per_ton_offshore_storage_costs -> 19.088937
A15: B.Link_region_hub_to_offshore_storage | B15: CO2 | C15: NLC6 | D15: NSNL031 | E15: =IF(F15<>"",(IF(F15<Info!$E$27,"pipeline","shipping")),"-") -> pipeline | F15: 84.548763 | G15: =IF(E15="pipeline",CO2_netw_links_and_costs_IC1!F15*pipe_a+pipe_b,CO2_netw_links_and_costs_IC1!F15*ship_a+ship_b)+per_ton_offshore_storage_costs -> 19.697956
A16: B.Link_region_hub_to_offshore_storage | B16: CO2 | C16: IT | D16: WMITN1 | E16: =IF(F16<>"",(IF(F16<Info!$E$27,"pipeline","shipping")),"-") -> pipeline | F16: 189.67914 | G16: =IF(E16="pipeline",CO2_netw_links_and_costs_IC1!F16*pipe_a+pipe_b,CO2_netw_links_and_costs_IC1!F16*ship_a+ship_b)+per_ton_offshore_storage_costs -> 24.356282
A17: B.Link_region_hub_to_offshore_storage | B17: CO2 | C17: UK | D17: NSUK041 | E17: =IF(F17<>"",(IF(F17<Info!$E$27,"pipeline","shipping")),"-") -> pipeline | F17: 217.74409 | G17: =IF(E17="pipeline",CO2_netw_links_and_costs_IC1!F17*pipe_a+pipe_b,CO2_netw_links_and_costs_IC1!F17*ship_a+ship_b)+per_ton_offshore_storage_costs -> 25.599841
A18: B.Link_region_hub_to_offshore_storage | B18: CO2 | C18: GR | D18: EMGR02 | E18: =IF(F18<>"",(IF(F18<Info!$E$27,"pipeline","shipping")),"-") -> pipeline | F18: 255.00563 | G18: =IF(E18="pipeline",CO2_netw_links_and_costs_IC1!F18*pipe_a+pipe_b,CO2_netw_links_and_costs_IC1!F18*ship_a+ship_b)+per_ton_offshore_storage_costs -> 27.250899
... A29: B.Link_region_hub_to_offshore_storage | B29: CO2 | C29: NO | D29: NSNOS22 | E29: =IF(F29<>"",(IF(F29<Info!$E$27,"pipeline","shipping")),"-") -> shipping | F29: 929.19838 | G29: =IF(E29="pipeline",CO2_netw_links_and_costs_IC1!F29*pipe_a+pipe_b,CO2_netw_links_and_costs_IC1!F29*ship_a+ship_b)+per_ton_offshore_storage_costs -> 55.02566
A30: C.Link_region_hub_to_region_hub(via harbors) | B30: CO2 | C30: NLC6 | D30: DE | E30: =IF(F30<>"",(IF(F30<Info!$E$27,"pipeline","shipping")),"-") -> pipeline | F30: 427.06847 | G30: =IF(E30="pipeline",CO2_netw_links_and_costs_IC1!F30*pipe_a+pipe_b,CO2_netw_links_and_costs_IC1!F30*ship_a+ship_b) -> 18.923404
A31: C.Link_region_hub_to_region_hub(via harbors) | B31: CO2 | C31: DK | D31: NLC5 | E31: =IF(F31<>"",(IF(F31<Info!$E$27,"pipeline","shipping")),"-") -> pipeline | F31: 442.80227 | G31: =IF(E31="pipeline",CO2_netw_links_and_costs_IC1!F31*pipe_a+pipe_b,CO2_netw_links_and_costs_IC1!F31*ship_a+ship_b) -> 19.620568
A32: C.Link_region_hub_to_region_hub(via harbors) | B32: CO2 | C32: BEC1 | D32: DE | E32: =IF(F32<>"",(IF(F32<Info!$E$27,"pipeline","shipping")),"-") -> pipeline | F32: 457.4356 | G32: =IF(E32="pipeline",CO2_netw_links_and_costs_IC1!F32*pipe_a+pipe_b,CO2_netw_links_and_costs_IC1!F32*ship_a+ship_b) -> 20.268971
A33: C.Link_region_hub_to_region_hub(via harbors) | B33: CO2 | C33: NLC5 | D33: UK | E33: =IF(F33<>"",(IF(F33<Info!$E$27,"pipeline","shipping")),"-") -> pipeline | F33: 494.04473 | G33: =IF(E33="pipeline",CO2_netw_links_and_costs_IC1!F33*pipe_a+pipe_b,CO2_netw_links_and_costs_IC1!F33*ship_a+ship_b) -> 21.891122
A34: C.Link_region_hub_to_region_hub(via harbors) | B34: CO2 | C34: NLC6 | D34: DK | E34: =IF(F34<>"",(IF(F34<Info!$E$27,"pipeline","shipping")),"-") -> pipeline | F34: 494.31453 | G34: =IF(E34="pipeline",CO2_netw_links_and_costs_IC1!F34*pipe_a+pipe_b,CO2_netw_links_and_costs_IC1!F34*ship_a+ship_b) -> 21.903077
A35: C.Link_region_hub_to_region_hub(via harbors) | B35: CO2 | C35: NLC6 | D35: UK | E35: =IF(F35<>"",(IF(F35<Info!$E$27,"pipeline","shipping")),"-") -> pipeline | F35: 495.50507 | G35: =IF(E35="pipeline",CO2_netw_links_and_costs_IC1!F35*pipe_a+pipe_b,CO2_netw_links_and_costs_IC1!F35*ship_a+ship_b) -> 21.95583
A36: C.Link_region_hub_to_region_hub(via harbors) | B36: CO2 | C36: BEC8 | D36: UK | E36: =IF(F36<>"",(IF(F36<Info!$E$27,"pipeline","shipping")),"-") -> pipeline | F36: 496.95957 | G36: =IF(E36="pipeline",CO2_netw_links_and_costs_IC1!F36*pipe_a+pipe_b,CO2_netw_links_and_costs_IC1!F36*ship_a+ship_b) -> 22.020279
A37: C.Link_region_hub_to_region_hub(via harbors) | B37: CO2 | C37: BEC4 | D37: UK | E37: =IF(F37<>"",(IF(F37<Info!$E$27,"pipeline","shipping")),"-") -> pipeline | F37: 508.63525 | G37: =IF(E37="pipeline",CO2_netw_links_and_costs_IC1!F37*pipe_a+pipe_b,CO2_netw_links_and_costs_IC1!F37*ship_a+ship_b) -> 22.537628
A38: C.Link_region_hub_to_region_hub(via harbors) | B38: CO2 | C38: BEC4 | D38: DE | E38: =IF(F38<>"",(IF(F38<Info!$E$27,"pipeline","shipping")),"-") -> pipeline | F38: 509.52728 | G38: =IF(E38="pipeline",CO2_netw_links_and_costs_IC1!F38*pipe_a+pipe_b,CO2_netw_links_and_costs_IC1!F38*ship_a+ship_b) -> 22.577154
A39: C.Link_region_hub_to_region_hub(via harbors) | B39: CO2 | C39: BEC1 | D39: UK | E39: =IF(F39<>"",(IF(F39<Info!$E$27,"pipeline","shipping")),"-") -> pipeline | F39: 530.0304 | G39: =IF(E39="pipeline",CO2_netw_links_and_costs_IC1!F39*pipe_a+pipe_b,CO2_netw_links_and_costs_IC1!F39*ship_a+ship_b) -> 23.485647
A40: C.Link_region_hub_to_region_hub(via harbors) | B40: CO2 | C40: BEC1 | D40: DK | E40: =IF(F40<>"",(IF(F40<Info!$E$27,"pipeline","shipping")),"-") -> pipeline | F40: 540.34025 | G40: =IF(E40="pipeline",CO2_netw_links_and_costs_IC1!F40*pipe_a+pipe_b,CO2_netw_links_and_costs_IC1!F40*ship_a+ship_b) -> 23.942477
A41: C.Link_region_hub_to_region_hub(via harbors) | B41: CO2 | C41: BEC8 | D41: DE | E41: =IF(F41<>"",(IF(F41<Info!$E$27,"pipeline","shipping")),"-") -> pipeline | F41: 546.61719 | G41: =IF(E41="pipeline",CO2_netw_links_and_costs_IC1!F41*pipe_a+pipe_b,CO2_netw_links_and_costs_IC1!F41*ship_a+ship_b) -> 24.220608
... A200: D.Link_region_hub_to_region_hub | B200: CO2 | C200: MT | D200: ES | E200: =IF(F200<>"",(IF(F200<Info!$E$27,"pipeline","shipping")),"-") -> shipping | F200: 1641 | G200: =IF(E200="pipeline",CO2_netw_links_and_costs_IC1!F200*pipe_a+pipe_b,CO2_netw_links_and_costs_IC1!F200*ship_a+ship_b) -> 47.9004

Sheet shipping_costs
C1: medium pressure
C2: up to 50.000 tonnes
H3: US_dollar2025/ton CO2 | I3: EU2025/ton_CO2
A4: 1 Mtpa | B4: distance km | C4: Liquefaction | D4: Intermediate Storage | E4: Conditioning | F4: Ships | G4: Loading and Unloading | H4: Total | I4: Total
B5: 500 | C5: 16.28 | D5: 11.87 | E5: 2.8 | F5: 11.78 | G5: 0.15 | H5: =SUM(C5:G5) -> 42.88 | I5: =H5*exchange_rate_USD25_EUR25 -> 38.000256
B6: 1000 | C6: 16.28 | D6: 17.8 | E6: 2.8 | F6: 13.98 | G6: 0.23 | H6: =SUM(C6:G6) -> 51.09 | I6: =H6*exchange_rate_USD25_EUR25 -> 45.275958
B7: 1500 | C7: 16.28 | D7: 23.74 | E7: 2.8 | F7: 15.75 | G7: 0.3 | H7: =SUM(C7:G7) -> 58.87 | I7: =H7*exchange_rate_USD25_EUR25 -> 52.170594
B8: 2000 | C8: 16.28 | D8: 29.67 | E8: 2.8 | F8: 17.26 | G8: 0.38 | H8: =SUM(C8:G8) -> 66.39 | I8: =H8*exchange_rate_USD25_EUR25 -> 58.834818
A9: 2 Mtpa | B9: distance km | C9: Liquefaction | D9: Intermediate Storage | E9: Conditioning | F9: Ships | G9: Loading and Unloading | H9: Total | I9: Total
B10: 500 | C10: 16.28 | D10: 11.87 | E10: 2.8 | F10: 7 | G10: 0.15 | H10: =SUM(C10:G10) -> 38.1 | I10: =H10*exchange_rate_USD25_EUR25 -> 33.76422
B11: 1000 | C11: 16.28 | D11: 17.8 | E11: 2.8 | F11: 8 | G11: 0.23 | H11: =SUM(C11:G11) -> 45.11 | I11: =H11*exchange_rate_USD25_EUR25 -> 39.976482
B12: 1500 | C12: 16.28 | D12: 23.74 | E12: 2.8 | F12: 9 | G12: 0.3 | H12: =SUM(C12:G12) -> 52.12 | I12: =H12*exchange_rate_USD25_EUR25 -> 46.188744
B13: 2000 | C13: 16.28 | D13: 29.67 | E13: 2.8 | F13: 10 | G13: 0.38 | H13: =SUM(C13:G13) -> 59.13 | I13: =H13*exchange_rate_USD25_EUR25 -> 52.401006
B15: Source: | C15: Barlow et al. (2025) Advancements in CCS technology and costs. Global CCS Institute.
B19: a | C19: 0.0124
B20: b | C20: 27.552
B22: km | C22: shipping costs [euro2025/ton]
B23: 50 | C23: =C$19*$B23+C$20 -> 28.172
B24: =B23+25 -> 75 | C24: =C$19*$B24+C$20 -> 28.482
B25: =B24+25 -> 100 | C25: =C$19*$B25+C$20 -> 28.792
B26: =B25+25 -> 125 | C26: =C$19*$B26+C$20 -> 29.102
B27: =B26+25 -> 150 | C27: =C$19*$B27+C$20 -> 29.412
B28: =B27+25 -> 175 | C28: =C$19*$B28+C$20 -> 29.722
B29: =B28+25 -> 200 | C29: =C$19*$B29+C$20 -> 30.032
B30: =B29+25 -> 225 | C30: =C$19*$B30+C$20 -> 30.342
B31: =B30+25 -> 250 | C31: =C$19*$B31+C$20 -> 30.652
B32: =B31+25 -> 275 | C32: =C$19*$B32+C$20 -> 30.962
B33: =B32+25 -> 300 | C33: =C$19*$B33+C$20 -> 31.272
B34: =B33+25 -> 325 | C34: =C$19*$B34+C$20 -> 31.582
B35: =B34+25 -> 350 | C35: =C$19*$B35+C$20 -> 31.892
... B81: =B80+25 -> 1500 | C81: =C$19*$B81+C$20 -> 46.152

Sheet storage_costs
A1: Source | B1: Hatta et al. (2025) Costs of CO2 Storage. Global CCS Institute: https://www.globalccsinstitute.com/wp-content/uploads/2025/12/Cost-of-CO2-Storage-1225.pdf
A2: onshore storage | B2: =(15+2)/2 -> 8.5 | C2: USD2025/ton
A3: offshore storage | B3: =(5+31)/2 -> 18 | C3: USD2025/ton

Sheet pipeline_costs
B1: Assuming 2 Mtpa | E1: Barlow et al (2025), flows exceeding 1 Mtpa through pipelines will only yield modest cost reductions (most economies of scale have been reached)
B2: avg | C2: 0.05 | D2: usd/km/tonne
B5: a | C5: =C2*Info!E34 -> 0.04431 | D5: euro2025/km/tonne
B6: b | C6: 0 | D6: euro2025/km/tonne
A8: km
A9: 50 | B9: =$A9*C$5+C$6 -> 2.2155
A10: =A9+25 -> 75 | B10: =$A10*C$5+C$6 -> 3.32325
A11: =A10+25 -> 100 | B11: =$A11*C$5+C$6 -> 4.431
A12: =A11+25 -> 125 | B12: =$A12*C$5+C$6 -> 5.53875
A13: =A12+25 -> 150 | B13: =$A13*C$5+C$6 -> 6.6465
A14: =A13+25 -> 175 | B14: =$A14*C$5+C$6 -> 7.75425
A15: =A14+25 -> 200 | B15: =$A15*C$5+C$6 -> 8.862
A16: =A15+25 -> 225 | B16: =$A16*C$5+C$6 -> 9.96975
A17: =A16+25 -> 250 | B17: =$A17*C$5+C$6 -> 11.0775
A18: =A17+25 -> 275 | B18: =$A18*C$5+C$6 -> 12.18525
A19: =A18+25 -> 300 | B19: =$A19*C$5+C$6 -> 13.293
A20: =A19+25 -> 325 | B20: =$A20*C$5+C$6 -> 14.40075
A21: =A20+25 -> 350 | B21: =$A21*C$5+C$6 -> 15.5085
... A67: =A66+25 -> 1500 | B67: =$A67*C$5+C$6 -> 66.465

Sheet X_Y_CO2_harbor_hubs
B1: CO2_Harbor_Hubs(CHH) | C1: description | D1: xcoordinate | E1: ycoordinate
A2: 1 | B2: CHH_west_med_ES | C2: CO2 Harbor Hub West Mediterranian (Barcelona harbor, ES) | D2: 2.18 | E2: 41.346 | F2: https://www.portdebarcelona.cat/en/communication/news/port-barcelonas-energy-transition-plan-will-enable-85-reduction-co2-emissions-2040
A3: 2 | B3: CHH_mid_med_IT | C3: CO2 Harbor Hub Adriatic sea ravenna (Italy) | D3: 12.261 | E3: 44.468 | F3: CCS Eni-Snam: Ravenna Hub
A4: 3 | B4: CHH_east_med_GR | C4: CO2 Harbor Hub east mediterranian Prinos (GR) | D4: 24.578 | E4: 40.761 | F4: Prinos CO2 | Energean PLC
A5: 4 | B5: CHH_baltics_LT | C5: CO2 Harbor Hub Baltics Klaipeda (LT) | D5: 21.13 | E5: 55.69 | F5: Klaipėda's CO₂ terminal recognised as part of the energy system - CCS Baltic Consortium project
A6: 5 | B6: CHH_southwest_NL | C6: CO2 Harbor Hub Rotterdam harbor (NL) | D6: 4.05 | E6: 51.95 | F6: Opslag en gebruik van CO2 | Port of Rotterdam
A7: 6 | B7: CHH_north_NL | C7: CO2 Harbor Hub Eemshaven harbor (NL) | D7: 6.833 | E7: 53.45 | F7: H2M Eemshaven - CarbonStorage
A8: 7 | B8: CHH_northwest_NL | C8: CO2 Harbor Hub Amsterdam harbor (NL) | D8: 4.808 | E8: 52.412 | F8: Amsterdam project | SeaSeaS
A9: 8 | B9: CHH_eastcoast_UK | C9: CO2 Harbor Hub Middlesborough port (UK) | D9: -1.242 | E9: 54.589 | F9: East Coast Cluster
A10: 9 | B10: CHH_westcoast_UK | C10: CO2 Harbor Hub Liverpool port (UK) | D10: -2.996 | E10: 53.406 | F10: HyNet hub
A11: 10 | B11: CHH_IE | C11: CO2 Harbor Hub Dublin port (IE) | D11: -6.189 | E11: 53.35 | F11: Ervia Cork CCUS
A12: 11 | B12: CHH_southwest_NO | C12: CO2 Harbor Hub Bergen port (NO) | D12: 5.309 | E12: 60.392 | F12: The Northern Lights project - Equinor
A13: 12 | B13: CHH_northwest_NO | C13: CO2 Harbor Hub Hammerfest port (NO) | D13: 23.683 | E13: 70.663 | F13: Snøhvit and Hammerfest LNG - Equinor
... A18: 17 | B18: CHH_DK | C18: CO2 Harbor Hub Esbjerg port (DK) | D18: 8.434 | E18: 55.464 | F18: https://www.ineos.com/news/shared-news/construction-begins-on-greensands-co-transit-terminal-at-port-esbjerg.-the-first-gateway-for-carbon-storage-in-the-eu/

Sheet X_Y_offshore_storage_hub
A1: OFF3 | C1: xcoordinates | D1: ycoordinates | E1: weighted avg capacity location?
A2: NSDE011 | B2: ="offsh_CO2_storage_"&""&A2 -> offsh_CO2_storage_NSDE011 | C2: =ROUND((IF($E2=1,VLOOKUP($A2,$A$28:$G$34,6,FALSE),VLOOKUP($A2,$A$38:$G$76,6,FALSE))),3) -> 6.5 | D2: =ROUND((IF($E2=1,VLOOKUP($A2,$A$28:$G$34,7,FALSE),VLOOKUP($A2,$A$38:$G$76,7,FALSE))),3) -> 54.5
A3: NSDKW12 | B3: ="offsh_CO2_storage_"&""&A3 -> offsh_CO2_storage_NSDKW12 | C3: =ROUND((IF($E3=1,VLOOKUP($A3,$A$28:$G$34,6,FALSE),VLOOKUP($A3,$A$38:$G$76,6,FALSE))),3) -> 5.082 | D3: =ROUND((IF($E3=1,VLOOKUP($A3,$A$28:$G$34,7,FALSE),VLOOKUP($A3,$A$38:$G$76,7,FALSE))),3) -> 56.367 | E3: 1
A4: WMES06 | B4: ="offsh_CO2_storage_"&""&A4 -> offsh_CO2_storage_WMES06 | C4: =ROUND((IF($E4=1,VLOOKUP($A4,$A$28:$G$34,6,FALSE),VLOOKUP($A4,$A$38:$G$76,6,FALSE))),3) -> 1.27 | D4: =ROUND((IF($E4=1,VLOOKUP($A4,$A$28:$G$34,7,FALSE),VLOOKUP($A4,$A$38:$G$76,7,FALSE))),3) -> 40.6
A5: EMGR02 | B5: ="offsh_CO2_storage_"&""&A5 -> offsh_CO2_storage_EMGR02 | C5: =ROUND((IF($E5=1,VLOOKUP($A5,$A$28:$G$34,6,FALSE),VLOOKUP($A5,$A$38:$G$76,6,FALSE))),3) -> 24.625 | D5: =ROUND((IF($E5=1,VLOOKUP($A5,$A$28:$G$34,7,FALSE),VLOOKUP($A5,$A$38:$G$76,7,FALSE))),3) -> 40.967
A6: ATIE03 | B6: ="offsh_CO2_storage_"&""&A6 -> offsh_CO2_storage_ATIE03 | C6: =ROUND((IF($E6=1,VLOOKUP($A6,$A$28:$G$34,6,FALSE),VLOOKUP($A6,$A$38:$G$76,6,FALSE))),3) -> -8.251 | D6: =ROUND((IF($E6=1,VLOOKUP($A6,$A$28:$G$34,7,FALSE),VLOOKUP($A6,$A$38:$G$76,7,FALSE))),3) -> 51.8
A7: WMITN1 | B7: ="offsh_CO2_storage_"&""&A7 -> offsh_CO2_storage_WMITN1 | C7: =ROUND((IF($E7=1,VLOOKUP($A7,$A$28:$G$34,6,FALSE),VLOOKUP($A7,$A$38:$G$76,6,FALSE))),3) -> 12.287 | D7: =ROUND((IF($E7=1,VLOOKUP($A7,$A$28:$G$34,7,FALSE),VLOOKUP($A7,$A$38:$G$76,7,FALSE))),3) -> 44.495
A8: NSNL012 | B8: ="offsh_CO2_storage_"&""&A8 -> offsh_CO2_storage_NSNL012 | C8: =ROUND((IF($E8=1,VLOOKUP($A8,$A$28:$G$34,6,FALSE),VLOOKUP($A8,$A$38:$G$76,6,FALSE))),3) -> 4.117 | D8: =ROUND((IF($E8=1,VLOOKUP($A8,$A$28:$G$34,7,FALSE),VLOOKUP($A8,$A$38:$G$76,7,FALSE))),3) -> 53.645 | E8: 1
A9: NSNL031 | B9: ="offsh_CO2_storage_"&""&A9 -> offsh_CO2_storage_NSNL031 | C9: =ROUND((IF($E9=1,VLOOKUP($A9,$A$28:$G$34,6,FALSE),VLOOKUP($A9,$A$38:$G$76,6,FALSE))),3) -> 4.021 | D9: =ROUND((IF($E9=1,VLOOKUP($A9,$A$28:$G$34,7,FALSE),VLOOKUP($A9,$A$38:$G$76,7,FALSE))),3) -> 52.435 | E9: 1
A10: ASNON1 | B10: ="offsh_CO2_storage_"&""&A10 -> offsh_CO2_storage_ASNON1 | C10: =ROUND((IF($E10=1,VLOOKUP($A10,$A$28:$G$34,6,FALSE),VLOOKUP($A10,$A$38:$G$76,6,FALSE))),3) -> 23.884 | D10: =ROUND((IF($E10=1,VLOOKUP($A10,$A$28:$G$34,7,FALSE),VLOOKUP($A10,$A$38:$G$76,7,FALSE))),3) -> 71.276 | E10: 1
A11: ASNOS3 | B11: ="offsh_CO2_storage_"&""&A11 -> offsh_CO2_storage_ASNOS3 | C11: =ROUND((IF($E11=1,VLOOKUP($A11,$A$28:$G$34,6,FALSE),VLOOKUP($A11,$A$38:$G$76,6,FALSE))),3) -> 3.553 | D11: =ROUND((IF($E11=1,VLOOKUP($A11,$A$28:$G$34,7,FALSE),VLOOKUP($A11,$A$38:$G$76,7,FALSE))),3) -> 60.38 | E11: 1
A12: NSNOS22 | B12: ="offsh_CO2_storage_"&""&A12 -> offsh_CO2_storage_NSNOS22 | C12: =ROUND((IF($E12=1,VLOOKUP($A12,$A$28:$G$34,6,FALSE),VLOOKUP($A12,$A$38:$G$76,6,FALSE))),3) -> 2.921 | D12: =ROUND((IF($E12=1,VLOOKUP($A12,$A$28:$G$34,7,FALSE),VLOOKUP($A12,$A$38:$G$76,7,FALSE))),3) -> 58.05 | E12: 1
A13: ASUK051 | B13: ="offsh_CO2_storage_"&""&A13 -> offsh_CO2_storage_ASUK051 | C13: =ROUND((IF($E13=1,VLOOKUP($A13,$A$28:$G$34,6,FALSE),VLOOKUP($A13,$A$38:$G$76,6,FALSE))),3) -> 1.55 | D13: =ROUND((IF($E13=1,VLOOKUP($A13,$A$28:$G$34,7,FALSE),VLOOKUP($A13,$A$38:$G$76,7,FALSE))),3) -> 61.38
A14: ATUK031 | B14: ="offsh_CO2_storage_"&""&A14 -> offsh_CO2_storage_ATUK031 | C14: =ROUND((IF($E14=1,VLOOKUP($A14,$A$28:$G$34,6,FALSE),VLOOKUP($A14,$A$38:$G$76,6,FALSE))),3) -> -2.843 | D14: =ROUND((IF($E14=1,VLOOKUP($A14,$A$28:$G$34,7,FALSE),VLOOKUP($A14,$A$38:$G$76,7,FALSE))),3) -> 53.277
A15: ATUK043 | B15: ="offsh_CO2_storage_"&""&A15 -> offsh_CO2_storage_ATUK043 | C15: =ROUND((IF($E15=1,VLOOKUP($A15,$A$28:$G$34,6,FALSE),VLOOKUP($A15,$A$38:$G$76,6,FALSE))),3) -> -3.2 | D15: =ROUND((IF($E15=1,VLOOKUP($A15,$A$28:$G$34,7,FALSE),VLOOKUP($A15,$A$38:$G$76,7,FALSE))),3) -> 54.05
A16: NSUK011 | B16: ="offsh_CO2_storage_"&""&A16 -> offsh_CO2_storage_NSUK011 | C16: =ROUND((IF($E16=1,VLOOKUP($A16,$A$28:$G$34,6,FALSE),VLOOKUP($A16,$A$38:$G$76,6,FALSE))),3) -> 1.478 | D16: =ROUND((IF($E16=1,VLOOKUP($A16,$A$28:$G$34,7,FALSE),VLOOKUP($A16,$A$38:$G$76,7,FALSE))),3) -> 52.853
A17: NSUK012 | B17: ="offsh_CO2_storage_"&""&A17 -> offsh_CO2_storage_NSUK012 | C17: =ROUND((IF($E17=1,VLOOKUP($A17,$A$28:$G$34,6,FALSE),VLOOKUP($A17,$A$38:$G$76,6,FALSE))),3) -> 2.17 | D17: =ROUND((IF($E17=1,VLOOKUP($A17,$A$28:$G$34,7,FALSE),VLOOKUP($A17,$A$38:$G$76,7,FALSE))),3) -> 53.08
A18: NSUK041 | B18: ="offsh_CO2_storage_"&""&A18 -> offsh_CO2_storage_NSUK041 | C18: =ROUND((IF($E18=1,VLOOKUP($A18,$A$28:$G$34,6,FALSE),VLOOKUP($A18,$A$38:$G$76,6,FALSE))),3) -> 0.4 | D18: =ROUND((IF($E18=1,VLOOKUP($A18,$A$28:$G$34,7,FALSE),VLOOKUP($A18,$A$38:$G$76,7,FALSE))),3) -> 53.9
A19: NSUK042 | B19: ="offsh_CO2_storage_"&""&A19 -> offsh_CO2_storage_NSUK042 | C19: =ROUND((IF($E19=1,VLOOKUP($A19,$A$28:$G$34,6,FALSE),VLOOKUP($A19,$A$38:$G$76,6,FALSE))),3) -> 1.303 | D19: =ROUND((IF($E19=1,VLOOKUP($A19,$A$28:$G$34,7,FALSE),VLOOKUP($A19,$A$38:$G$76,7,FALSE))),3) -> 54.197 | E19: 1
A20: NSUK052 | B20: ="offsh_CO2_storage_"&""&A20 -> offsh_CO2_storage_NSUK052 | C20: =ROUND((IF($E20=1,VLOOKUP($A20,$A$28:$G$34,6,FALSE),VLOOKUP($A20,$A$38:$G$76,6,FALSE))),3) -> 1.3 | D20: =ROUND((IF($E20=1,VLOOKUP($A20,$A$28:$G$34,7,FALSE),VLOOKUP($A20,$A$38:$G$76,7,FALSE))),3) -> 57.9
A26: weighted avg location based on capacity (if #projects>1)
A27: OFF3 | B27: PECD | C27: Project | D27: Country | E27: Storage Basin / Reservoir | F27: xcoordinates | G27: ycoordinates
A28: ASNON1 | B28: NO | C28: weighted_avg | D28: Norway | E28: Offshore storage | F28: =SUMPRODUCT($F$38:$F$39,$H$38:$H$39)/SUM($H$38:$H$39) -> 23.883784 | G28: =SUMPRODUCT($G$38:$G$39,$H$38:$H$39)/SUM($H$38:$H$39) -> 71.275676
A29: ASNOS3 | B29: NO | C29: weighted_avg | D29: Norway | E29: Offshore storage | F29: =SUMPRODUCT($F$40:$F$46,$H$40:$H$46)/SUM($H$40:$H$46) -> 3.5530265 | G29: =SUMPRODUCT($G$40:$G$46,$H$40:$H$46)/SUM($H$40:$H$46) -> 60.379802
A30: NSDKW12 | B30: DK | C30: weighted_avg | D30: Denmark | E30: Offshore storage | F30: =SUMPRODUCT($F$53:$F$54,$H$53:$H$54)/SUM($H$53:$H$54) -> 5.0818182 | G30: =SUMPRODUCT($G$53:$G$54,$H$53:$H$54)/SUM($H$53:$H$54) -> 56.367273
A31: NSNL012 | B31: NL | C31: weighted_avg | D31: Netherlands | E31: Offshore storage | F31: =SUMPRODUCT($F$55:$F$57,$H$55:$H$57)/SUM($H$55:$H$57) -> 4.1166533 | G31: =SUMPRODUCT($G$55:$G$57,$H$55:$H$57)/SUM($H$55:$H$57) -> 53.644735
A32: NSNL031 | B32: NL | C32: weighted_avg | D32: Netherlands | E32: Offshore storage | F32: =SUMPRODUCT($F$58:$F$60,$H$58:$H$60)/SUM($H$58:$H$60) -> 4.0208468 | G32: =SUMPRODUCT($G$58:$G$60,$H$58:$H$60)/SUM($H$58:$H$60) -> 52.435323
A33: NSNOS22 | B33: NO | C33: weighted_avg | D33: Norway | E33: Offshore storage | F33: =SUMPRODUCT($F$61:$F$63,$H$61:$H$63)/SUM($H$61:$H$63) -> 2.9212713 | G33: =SUMPRODUCT($G$61:$G$63,$H$61:$H$63)/SUM($H$61:$H$63) -> 58.050014
A34: NSUK042 | B34: UK | C34: weighted_avg | D34: United Kingdom | E34: Offshore storage | F34: =SUMPRODUCT($F$70:$F$72,$H$70:$H$72)/SUM($H$70:$H$72) -> 1.3030303 | G34: =SUMPRODUCT($G$70:$G$72,$H$70:$H$72)/SUM($H$70:$H$72) -> 54.19697
A36: All projects
A37: OFF3 | B37: PECD | C37: Project | D37: Country | E37: Storage Basin / Reservoir | F37: xcoordinates | G37: ycoordinates | H37: Max_capacity
A38: ASNON1 | B38: NO | C38: Snøhvit CO₂ Storage | D38: Norway | E38: Offshore storage | F38: 22.1 | G38: 71.6 | H38: 0.7
A39: ASNON1 | B39: NO | C39: Polaris / Barents Blue | D39: Norway | E39: Offshore storage | F39: 24.3 | G39: 71.2 | H39: 3
A40: ASNOS3 | B40: NO | C40: Northern Lights | D40: Norway | E40: Offshore storage | F40: 3.6889006 | G40: 60.568692 | H40: 5.2
A41: ASNOS3 | B41: NO | C41: Smeaheia | D41: Norway | E41: Offshore storage | F41: 4.077951 | G41: 60.652963 | H41: 20
A42: ASNOS3 | B42: NO | C42: Luna CCS | D42: Norway | E42: Offshore storage | F42: 3.2 | G42: 61 | H42: 5
A43: ASNOS3 | B43: NO | C43: Havstjerne | D43: Norway | E43: Offshore storage | F43: 2.8 | G43: 59.7 | H43: 7
A44: ASNOS3 | B44: NO | C44: Atlas | D44: Norway | E44: Offshore storage | F44: 3.12 | G44: 60.05 | H44: 6
A45: ASNOS3 | B45: NO | C45: Kinno | D45: Norway | E45: Offshore storage | F45: 3.19 | G45: 59.75 | H45: 5
A46: ASNOS3 | B46: NO | C46: Northern Lights - extension | D46: Norway | E46: Offshore storage | F46: 3.6889006 | G46: 60.568692 | H46: 1.8
...

Sheet neighbors_cargo_data
A3: =B3&" "&C3 -> AL GR | B3: AL | C3: GR
A4: =B4&" "&C4 -> AL ME | B4: AL | C4: ME
A5: =B5&" "&C5 -> AL MK | B5: AL | C5: MK
A6: =B6&" "&C6 -> AL XK | B6: AL | C6: XK
A7: =B7&" "&C7 -> AT CH | B7: AT | C7: CH
A8: =B8&" "&C8 -> AT CZ | B8: AT | C8: CZ
A9: =B9&" "&C9 -> AT DE | B9: AT | C9: DE
A10: =B10&" "&C10 -> AT HU | B10: AT | C10: HU
A11: =B11&" "&C11 -> AT IT | B11: AT | C11: IT
A12: =B12&" "&C12 -> AT SI | B12: AT | C12: SI
A13: =B13&" "&C13 -> AT SK | B13: AT | C13: SK
A14: =B14&" "&C14 -> BA HR | B14: BA | C14: HR
... A190: =B190&" "&C190 -> XK RS | B190: XK | C190: RS
